Workbook

Sheet січень
A1: ОСББ "Карбишева - 22" | N1: 37465042
B2: Відомість нарахувань та оплати мешканців за утримання будинку | V2: тариф | W2: 4.1
B3: у січні 2023 року
A6: № кв. | B6: ПІБ | C6: Особ. рах. | D6: Д-Т | E6: К-Т | F6: Пільга % | G6: Заг.площа | H6: Пільг. Площа | I6: Внески | J6: 100% нарах. | K6: Пільгова сума | L6: сплачені суми пільг за реєстрами | M6: Коригування | N6: До сплати | O6: Сплачено | P6: Д-Т | Q6: К-Т
A7: 1 | B7: Бережний В.М. | C7: 1001 | D7: 1051.23 | E7: 0 | F7: 0 | G7: 64.26 | H7: 0 | I7: =W$2 -> 4.1 | J7: =ROUND(G7*I7,2) -> 263.47 | N7: =ROUND((G7*I7)-K7-L7-M7,2) -> 263.47 | P7: =IF(D7=0,IF((N7-E7-O7)>0,(N7-E7-O7),0),IF((D7+N7-O7)>0,(D7+N7-O7),0)) -> 1314.7 | Q7: =IF(E7=0,IF((D7+N7-O7)<0,ABS(D7+N7-O7),0),IF((N7-E7-O7)<0,ABS(N7-E7-O7),0)) -> 0
A8: 2 | B8: Старикова Т.О. | C8: 1002 | D8: 2324.06 | E8: 0 | F8: 0 | G8: 48.71 | H8: 0 | I8: =W$2 -> 4.1 | J8: =ROUND(G8*I8,2) -> 199.71 | N8: =ROUND((G8*I8)-K8-L8-M8,2) -> 199.71 | P8: =IF(D8=0,IF((N8-E8-O8)>0,(N8-E8-O8),0),IF((D8+N8-O8)>0,(D8+N8-O8),0)) -> 2523.77 | Q8: =IF(E8=0,IF((D8+N8-O8)<0,ABS(D8+N8-O8),0),IF((N8-E8-O8)<0,ABS(N8-E8-O8),0)) -> 0
A9: 3 | B9: Мазур Т.В. | C9: 1003 | D9: 137.5 | E9: 0 | F9: 0 | G9: 35 | H9: 0 | I9: =W$2 -> 4.1 | J9: =ROUND(G9*I9,2) -> 143.5 | N9: =ROUND((G9*I9)-K9-L9-M9,2) -> 143.5 | P9: =IF(D9=0,IF((N9-E9-O9)>0,(N9-E9-O9),0),IF((D9+N9-O9)>0,(D9+N9-O9),0)) -> 281 | Q9: =IF(E9=0,IF((D9+N9-O9)<0,ABS(D9+N9-O9),0),IF((N9-E9-O9)<0,ABS(N9-E9-O9),0)) -> 0
A10: 4 | B10: Сокол О.В. | C10: 1004 | D10: 0 | E10: 0.03 | F10: 0 | G10: 61.6 | H10: 0 | I10: =W$2 -> 4.1 | J10: =ROUND(G10*I10,2) -> 252.56 | N10: =ROUND((G10*I10)-K10-L10-M10,2) -> 252.56 | O10: =252.56 -> 252.56 | P10: =IF(D10=0,IF((N10-E10-O10)>0,(N10-E10-O10),0),IF((D10+N10-O10)>0,(D10+N10-O10),0)) -> 0 | Q10: =IF(E10=0,IF((D10+N10-O10)<0,ABS(D10+N10-O10),0),IF((N10-E10-O10)<0,ABS(N10-E10-O10),0)) -> 0.03
A11: 5 | B11: Семко Л.І. | C11: 1005 | D11: 161.03 | E11: 0 | F11: 0 | G11: 28.34 | H11: 0 | I11: =W$2 -> 4.1 | J11: =ROUND(G11*I11,2) -> 116.19 | N11: =ROUND((G11*I11)-K11-L11-M11,2) -> 116.19 | P11: =IF(D11=0,IF((N11-E11-O11)>0,(N11-E11-O11),0),IF((D11+N11-O11)>0,(D11+N11-O11),0)) -> 277.22 | Q11: =IF(E11=0,IF((D11+N11-O11)<0,ABS(D11+N11-O11),0),IF((N11-E11-O11)<0,ABS(N11-E11-O11),0)) -> 0
A12: 5 | B12: Гаркуша Н.І. | C12: 1005-а | D12: 598.1 | E12: 0 | F12: 0 | G12: 36.66 | H12: 0 | I12: =W$2 -> 4.1 | J12: =ROUND(G12*I12,2) -> 150.31 | N12: =ROUND((G12*I12)-K12-L12-M12,2) -> 150.31 | O12: 500 | P12: =IF(D12=0,IF((N12-E12-O12)>0,(N12-E12-O12),0),IF((D12+N12-O12)>0,(D12+N12-O12),0)) -> 248.41 | Q12: =IF(E12=0,IF((D12+N12-O12)<0,ABS(D12+N12-O12),0),IF((N12-E12-O12)<0,ABS(N12-E12-O12),0)) -> 0
A13: 6 | B13: Андріяшев В.М | C13: 1006 | D13: 1264.08 | E13: 0 | F13: 0 | G13: 49.8 | H13: 0 | I13: =W$2 -> 4.1 | J13: =ROUND(G13*I13,2) -> 204.18 | N13: =ROUND((G13*I13)-K13-L13-M13,2) -> 204.18 | P13: =IF(D13=0,IF((N13-E13-O13)>0,(N13-E13-O13),0),IF((D13+N13-O13)>0,(D13+N13-O13),0)) -> 1468.26 | Q13: =IF(E13=0,IF((D13+N13-O13)<0,ABS(D13+N13-O13),0),IF((N13-E13-O13)<0,ABS(N13-E13-O13),0)) -> 0
A14: 7 | B14: Старчикова О.М. | C14: 1007 | D14: 0 | E14: 0.16 | F14: 0 | G14: 34.65 | H14: 0 | I14: =W$2 -> 4.1 | J14: =ROUND(G14*I14,2) -> 142.07 | N14: =ROUND((G14*I14)-K14-L14-M14,2) -> 142.07 | O14: 143 | P14: =IF(D14=0,IF((N14-E14-O14)>0,(N14-E14-O14),0),IF((D14+N14-O14)>0,(D14+N14-O14),0)) -> 0 | Q14: =IF(E14=0,IF((D14+N14-O14)<0,ABS(D14+N14-O14),0),IF((N14-E14-O14)<0,ABS(N14-E14-O14),0)) -> 1.09
A15: 8 | B15: Безер Т.М | C15: 1008 | D15: 1171.25 | E15: 0 | F15: 0 | G15: 62.14 | H15: 0 | I15: =W$2 -> 4.1 | J15: =ROUND(G15*I15,2) -> 254.77 | N15: =ROUND((G15*I15)-K15-L15-M15,2) -> 254.77 | O15: 1200 | P15: =IF(D15=0,IF((N15-E15-O15)>0,(N15-E15-O15),0),IF((D15+N15-O15)>0,(D15+N15-O15),0)) -> 226.02 | Q15: =IF(E15=0,IF((D15+N15-O15)<0,ABS(D15+N15-O15),0),IF((N15-E15-O15)<0,ABS(N15-E15-O15),0)) -> 0
A16: 9 | B16: Решетило М.М | C16: 1009 | D16: 2905.96 | E16: 0 | F16: 0 | G16: 65.16 | H16: 0 | I16: =W$2 -> 4.1 | J16: =ROUND(G16*I16,2) -> 267.16 | N16: =ROUND((G16*I16)-K16-L16-M16,2) -> 267.16 | P16: =IF(D16=0,IF((N16-E16-O16)>0,(N16-E16-O16),0),IF((D16+N16-O16)>0,(D16+N16-O16),0)) -> 3173.12 | Q16: =IF(E16=0,IF((D16+N16-O16)<0,ABS(D16+N16-O16),0),IF((N16-E16-O16)<0,ABS(N16-E16-O16),0)) -> 0
A17: 10 | B17: Фесенко О.В. | C17: 1010 | D17: 1581.93 | E17: 0 | F17: 0 | G17: 50.1 | H17: 0 | I17: =W$2 -> 4.1 | J17: =ROUND(G17*I17,2) -> 205.41 | N17: =ROUND((G17*I17)-K17-L17-M17,2) -> 205.41 | P17: =IF(D17=0,IF((N17-E17-O17)>0,(N17-E17-O17),0),IF((D17+N17-O17)>0,(D17+N17-O17),0)) -> 1787.34 | Q17: =IF(E17=0,IF((D17+N17-O17)<0,ABS(D17+N17-O17),0),IF((N17-E17-O17)<0,ABS(N17-E17-O17),0)) -> 0
A18: 11 | B18: Петренко О.М. | C18: 1011 | D18: 1352.68 | E18: 0 | F18: 0 | G18: 35.2 | H18: 0 | I18: =W$2 -> 4.1 | J18: =ROUND(G18*I18,2) -> 144.32 | N18: =ROUND((G18*I18)-K18-L18-M18,2) -> 144.32 | P18: =IF(D18=0,IF((N18-E18-O18)>0,(N18-E18-O18),0),IF((D18+N18-O18)>0,(D18+N18-O18),0)) -> 1497 | Q18: =IF(E18=0,IF((D18+N18-O18)<0,ABS(D18+N18-O18),0),IF((N18-E18-O18)<0,ABS(N18-E18-O18),0)) -> 0
A19: 12 | B19: Зеленюк А.Д | C19: 1012 | D19: 2913.21 | E19: 0 | F19: 0 | G19: 62.78 | H19: 0 | I19: =W$2 -> 4.1 | J19: =ROUND(G19*I19,2) -> 257.4 | N19: =ROUND((G19*I19)-K19-L19-M19,2) -> 257.4 | P19: =IF(D19=0,IF((N19-E19-O19)>0,(N19-E19-O19),0),IF((D19+N19-O19)>0,(D19+N19-O19),0)) -> 3170.61 | Q19: =IF(E19=0,IF((D19+N19-O19)<0,ABS(D19+N19-O19),0),IF((N19-E19-O19)<0,ABS(N19-E19-O19),0)) -> 0
A20: 13 | B20: Вовк І.В | C20: 1013 | D20: 2136.87 | E20: 0 | F20: 0 | G20: 28.23 | H20: 0 | I20: =W$2 -> 4.1 | J20: =ROUND(G20*I20,2) -> 115.74 | N20: =ROUND((G20*I20)-K20-L20-M20,2) -> 115.74 | P20: =IF(D20=0,IF((N20-E20-O20)>0,(N20-E20-O20),0),IF((D20+N20-O20)>0,(D20+N20-O20),0)) -> 2252.61 | Q20: =IF(E20=0,IF((D20+N20-O20)<0,ABS(D20+N20-O20),0),IF((N20-E20-O20)<0,ABS(N20-E20-O20),0)) -> 0
A21: 13 | B21: Романовський В.М | C21: 1013-а | D21: 3257.9 | E21: 0 | F21: 0 | G21: 37.84 | H21: 0 | I21: =W$2 -> 4.1 | J21: =ROUND(G21*I21,2) -> 155.14 | N21: =ROUND((G21*I21)-K21-L21-M21,2) -> 155.14 | P21: =IF(D21=0,IF((N21-E21-O21)>0,(N21-E21-O21),0),IF((D21+N21-O21)>0,(D21+N21-O21),0)) -> 3413.04 | Q21: =IF(E21=0,IF((D21+N21-O21)<0,ABS(D21+N21-O21),0),IF((N21-E21-O21)<0,ABS(N21-E21-O21),0)) -> 0
A22: 14 | B22: Ряба Л.І | C22: 1014 | D22: 1211.28 | E22: 0 | F22: 0 | G22: 49.24 | H22: 0 | I22: =W$2 -> 4.1 | J22: =ROUND(G22*I22,2) -> 201.88 | N22: =ROUND((G22*I22)-K22-L22-M22,2) -> 201.88 | O22: 500 | P22: =IF(D22=0,IF((N22-E22-O22)>0,(N22-E22-O22),0),IF((D22+N22-O22)>0,(D22+N22-O22),0)) -> 913.16 | Q22: =IF(E22=0,IF((D22+N22-O22)<0,ABS(D22+N22-O22),0),IF((N22-E22-O22)<0,ABS(N22-E22-O22),0)) -> 0
A23: 15 | B23: Кас'янова О.А. | C23: 1015 | D23: 909.04 | E23: 0 | F23: 0 | G23: 35.1 | H23: 0 | I23: =W$2 -> 4.1 | J23: =ROUND(G23*I23,2) -> 143.91 | N23: =ROUND((G23*I23)-K23-L23-M23,2) -> 143.91 | P23: =IF(D23=0,IF((N23-E23-O23)>0,(N23-E23-O23),0),IF((D23+N23-O23)>0,(D23+N23-O23),0)) -> 1052.95 | Q23: =IF(E23=0,IF((D23+N23-O23)<0,ABS(D23+N23-O23),0),IF((N23-E23-O23)<0,ABS(N23-E23-O23),0)) -> 0
A24: 16 | B24: Корякіна М.В. | C24: 1016 | D24: 1352.41 | E24: 0 | F24: 0 | G24: 61.9 | H24: 0 | I24: =W$2 -> 4.1 | J24: =ROUND(G24*I24,2) -> 253.79 | N24: =ROUND((G24*I24)-K24-L24-M24,2) -> 253.79 | P24: =IF(D24=0,IF((N24-E24-O24)>0,(N24-E24-O24),0),IF((D24+N24-O24)>0,(D24+N24-O24),0)) -> 1606.2 | Q24: =IF(E24=0,IF((D24+N24-O24)<0,ABS(D24+N24-O24),0),IF((N24-E24-O24)<0,ABS(N24-E24-O24),0)) -> 0
A25: 17 | B25: Сокерчак А.В. | C25: 1017 | D25: 1630.98 | E25: 0 | F25: 0 | G25: 66.3 | H25: 0 | I25: =W$2 -> 4.1 | J25: =ROUND(G25*I25,2) -> 271.83 | N25: =ROUND((G25*I25)-K25-L25-M25,2) -> 271.83 | O25: =815.49+815.49 -> 1630.98 | P25: =IF(D25=0,IF((N25-E25-O25)>0,(N25-E25-O25),0),IF((D25+N25-O25)>0,(D25+N25-O25),0)) -> 271.83 | Q25: =IF(E25=0,IF((D25+N25-O25)<0,ABS(D25+N25-O25),0),IF((N25-E25-O25)<0,ABS(N25-E25-O25),0)) -> 0
A26: 18 | B26: Кравченко В.А | C26: 1018 | D26: 0 | E26: 1406.07 | F26: 0 | G26: 51.48 | H26: 0 | I26: =W$2 -> 4.1 | J26: =ROUND(G26*I26,2) -> 211.07 | L26: 211.07 | N26: =ROUND((G26*I26)-K26-L26-M26,2) -> 0 | P26: =IF(D26=0,IF((N26-E26-O26)>0,(N26-E26-O26),0),IF((D26+N26-O26)>0,(D26+N26-O26),0)) -> 0 | Q26: =IF(E26=0,IF((D26+N26-O26)<0,ABS(D26+N26-O26),0),IF((N26-E26-O26)<0,ABS(N26-E26-O26),0)) -> 1406.07
A27: 19 | B27: Чичикало А.С | C27: 1019 | D27: 0 | E27: 1.62 | F27: 0 | G27: 35.1 | H27: 0 | I27: =W$2 -> 4.1 | J27: =ROUND(G27*I27,2) -> 143.91 | N27: =ROUND((G27*I27)-K27-L27-M27,2) -> 143.91 | P27: =IF(D27=0,IF((N27-E27-O27)>0,(N27-E27-O27),0),IF((D27+N27-O27)>0,(D27+N27-O27),0)) -> 142.29 | Q27: =IF(E27=0,IF((D27+N27-O27)<0,ABS(D27+N27-O27),0),IF((N27-E27-O27)<0,ABS(N27-E27-O27),0)) -> 0
A28: 20 | B28: Сільващук А.А | C28: 1020 | D28: 0 | E28: 1.0231815e-12 | F28: 0 | G28: 62.7 | H28: 0 | I28: =W$2 -> 4.1 | J28: =ROUND(G28*I28,2) -> 257.07 | N28: =ROUND((G28*I28)-K28-L28-M28,2) -> 257.07 | P28: =IF(D28=0,IF((N28-E28-O28)>0,(N28-E28-O28),0),IF((D28+N28-O28)>0,(D28+N28-O28),0)) -> 257.07 | Q28: =IF(E28=0,IF((D28+N28-O28)<0,ABS(D28+N28-O28),0),IF((N28-E28-O28)<0,ABS(N28-E28-O28),0)) -> 0
A29: 21 | B29: Стеценко Г.М | C29: 1021 | D29: 1703.73 | E29: 0 | F29: 0 | G29: 65.32 | H29: 0 | I29: =W$2 -> 4.1 | J29: =ROUND(G29*I29,2) -> 267.81 | N29: =ROUND((G29*I29)-K29-L29-M29,2) -> 267.81 | P29: =IF(D29=0,IF((N29-E29-O29)>0,(N29-E29-O29),0),IF((D29+N29-O29)>0,(D29+N29-O29),0)) -> 1971.54 | Q29: =IF(E29=0,IF((D29+N29-O29)<0,ABS(D29+N29-O29),0),IF((N29-E29-O29)<0,ABS(N29-E29-O29),0)) -> 0
A30: 22 | B30: Кирдячкіна П.А | C30: 1022 | D30: 1630.16 | E30: 0 | F30: 0 | G30: 49.7 | H30: 0 | I30: =W$2 -> 4.1 | J30: =ROUND(G30*I30,2) -> 203.77 | N30: =ROUND((G30*I30)-K30-L30-M30,2) -> 203.77 | O30: 630 | P30: =IF(D30=0,IF((N30-E30-O30)>0,(N30-E30-O30),0),IF((D30+N30-O30)>0,(D30+N30-O30),0)) -> 1203.93 | Q30: =IF(E30=0,IF((D30+N30-O30)<0,ABS(D30+N30-O30),0),IF((N30-E30-O30)<0,ABS(N30-E30-O30),0)) -> 0
A31: 23 | B31: Фоміченко Л.А | C31: 1023 | D31: 0 | E31: 3.9790393e-13 | F31: 0 | G31: 35.1 | H31: 0 | I31: =W$2 -> 4.1 | J31: =ROUND(G31*I31,2) -> 143.91 | N31: =ROUND((G31*I31)-K31-L31-M31,2) -> 143.91 | P31: =IF(D31=0,IF((N31-E31-O31)>0,(N31-E31-O31),0),IF((D31+N31-O31)>0,(D31+N31-O31),0)) -> 143.91 | Q31: =IF(E31=0,IF((D31+N31-O31)<0,ABS(D31+N31-O31),0),IF((N31-E31-O31)<0,ABS(N31-E31-O31),0)) -> 0
A32: 24 | B32: Сердюк А.Г | C32: 1024 | D32: 1628.61 | E32: 0 | F32: 0 | G32: 62.31 | H32: 0 | I32: =W$2 -> 4.1 | J32: =ROUND(G32*I32,2) -> 255.47 | N32: =ROUND((G32*I32)-K32-L32-M32,2) -> 255.47 | P32: =IF(D32=0,IF((N32-E32-O32)>0,(N32-E32-O32),0),IF((D32+N32-O32)>0,(D32+N32-O32),0)) -> 1884.08 | Q32: =IF(E32=0,IF((D32+N32-O32)<0,ABS(D32+N32-O32),0),IF((N32-E32-O32)<0,ABS(N32-E32-O32),0)) -> 0
A33: 25 | B33: Михальченко Г.М | C33: 1025 | D33: 2787.48 | E33: 0 | F33: 0 | G33: 65.04 | I33: =W$2 -> 4.1 | J33: =ROUND(G33*I33,2) -> 266.66 | N33: =ROUND((G33*I33)-K33-L33-M33,2) -> 266.66 | P33: =IF(D33=0,IF((N33-E33-O33)>0,(N33-E33-O33),0),IF((D33+N33-O33)>0,(D33+N33-O33),0)) -> 3054.14 | Q33: =IF(E33=0,IF((D33+N33-O33)<0,ABS(D33+N33-O33),0),IF((N33-E33-O33)<0,ABS(N33-E33-O33),0)) -> 0
A34: 26 | B34: Замуховська Я.С | C34: 1026 | D34: 1036.97 | E34: 0 | F34: 0 | G34: 49.8 | H34: 0 | I34: =W$2 -> 4.1 | J34: =ROUND(G34*I34,2) -> 204.18 | N34: =ROUND((G34*I34)-K34-L34-M34,2) -> 204.18 | P34: =IF(D34=0,IF((N34-E34-O34)>0,(N34-E34-O34),0),IF((D34+N34-O34)>0,(D34+N34-O34),0)) -> 1241.15 | Q34: =IF(E34=0,IF((D34+N34-O34)<0,ABS(D34+N34-O34),0),IF((N34-E34-O34)<0,ABS(N34-E34-O34),0)) -> 0
A35: 27 | B35: Мержиєвська Г.К | C35: 1027 | D35: 918.9 | E35: 0 | F35: 0 | G35: 35.17 | H35: 0 | I35: =W$2 -> 4.1 | J35: =ROUND(G35*I35,2) -> 144.2 | N35: =ROUND((G35*I35)-K35-L35-M35,2) -> 144.2 | P35: =IF(D35=0,IF((N35-E35-O35)>0,(N35-E35-O35),0),IF((D35+N35-O35)>0,(D35+N35-O35),0)) -> 1063.1 | Q35: =IF(E35=0,IF((D35+N35-O35)<0,ABS(D35+N35-O35),0),IF((N35-E35-O35)<0,ABS(N35-E35-O35),0)) -> 0
A36: 28 | B36: Кулакова Л.В. | C36: 1028 | D36: 2073.31 | E36: 0 | F36: 0 | G36: 62.47 | H36: 0 | I36: =W$2 -> 4.1 | J36: =ROUND(G36*I36,2) -> 256.13 | N36: =ROUND((G36*I36)-K36-L36-M36,2) -> 256.13 | O36: =200+1900 -> 2100 | P36: =IF(D36=0,IF((N36-E36-O36)>0,(N36-E36-O36),0),IF((D36+N36-O36)>0,(D36+N36-O36),0)) -> 229.44 | Q36: =IF(E36=0,IF((D36+N36-O36)<0,ABS(D36+N36-O36),0),IF((N36-E36-O36)<0,ABS(N36-E36-O36),0)) -> 0
A37: 29 | B37: Бочаров В.Л. | C37: 1029 | D37: 1478.64 | E37: 0 | F37: 0 | G37: 65.75 | H37: 0 | I37: =W$2 -> 4.1 | J37: =ROUND(G37*I37,2) -> 269.58 | N37: =ROUND((G37*I37)-K37-L37-M37,2) -> 269.58 | P37: =IF(D37=0,IF((N37-E37-O37)>0,(N37-E37-O37),0),IF((D37+N37-O37)>0,(D37+N37-O37),0)) -> 1748.22 | Q37: =IF(E37=0,IF((D37+N37-O37)<0,ABS(D37+N37-O37),0),IF((N37-E37-O37)<0,ABS(N37-E37-O37),0)) -> 0
A38: 30 | B38: Лучков В.Л. | C38: 1030 | D38: 2232.83 | E38: 0 | F38: 0 | G38: 49.7 | H38: 0 | I38: =W$2 -> 4.1 | J38: =ROUND(G38*I38,2) -> 203.77 | N38: =ROUND((G38*I38)-K38-L38-M38,2) -> 203.77 | P38: =IF(D38=0,IF((N38-E38-O38)>0,(N38-E38-O38),0),IF((D38+N38-O38)>0,(D38+N38-O38),0)) -> 2436.6 | Q38: =IF(E38=0,IF((D38+N38-O38)<0,ABS(D38+N38-O38),0),IF((N38-E38-O38)<0,ABS(N38-E38-O38),0)) -> 0
A39: 31 | B39: Кашкар Т.М. | C39: 1031 | D39: 0 | E39: 5.6843419e-14 | F39: 0 | G39: 35.1 | H39: 0 | I39: =W$2 -> 4.1 | J39: =ROUND(G39*I39,2) -> 143.91 | N39: =ROUND((G39*I39)-K39-L39-M39,2) -> 143.91 | O39: 143.91 | P39: =IF(D39=0,IF((N39-E39-O39)>0,(N39-E39-O39),0),IF((D39+N39-O39)>0,(D39+N39-O39),0)) -> 0 | Q39: =IF(E39=0,IF((D39+N39-O39)<0,ABS(D39+N39-O39),0),IF((N39-E39-O39)<0,ABS(N39-E39-O39),0)) -> 0
A40: 32 | B40: Стецюк Н.П. | C40: 1032 | D40: 1759.67 | E40: 0 | F40: 0 | G40: 61.9 | H40: 0 | I40: =W$2 -> 4.1 | J40: =ROUND(G40*I40,2) -> 253.79 | N40: =ROUND((G40*I40)-K40-L40-M40,2) -> 253.79 | P40: =IF(D40=0,IF((N40-E40-O40)>0,(N40-E40-O40),0),IF((D40+N40-O40)>0,(D40+N40-O40),0)) -> 2013.46 | Q40: =IF(E40=0,IF((D40+N40-O40)<0,ABS(D40+N40-O40),0),IF((N40-E40-O40)<0,ABS(N40-E40-O40),0)) -> 0
A41: 33 | B41: Маханько В.О. | C41: 1033 | D41: 1232.64 | E41: 0 | F41: 0 | G41: 65.53 | I41: =W$2 -> 4.1 | J41: =ROUND(G41*I41,2) -> 268.67 | L41: 268.67 | N41: =ROUND((G41*I41)-K41-L41-M41,2) -> 0 | P41: =IF(D41=0,IF((N41-E41-O41)>0,(N41-E41-O41),0),IF((D41+N41-O41)>0,(D41+N41-O41),0)) -> 1232.64 | Q41: =IF(E41=0,IF((D41+N41-O41)<0,ABS(D41+N41-O41),0),IF((N41-E41-O41)<0,ABS(N41-E41-O41),0)) -> 0
A42: 34 | B42: Реуцька Р.С. | C42: 1034 | D42: 925.74 | E42: 0 | F42: 0 | G42: 49.7 | H42: 0 | I42: =W$2 -> 4.1 | J42: =ROUND(G42*I42,2) -> 203.77 | N42: =ROUND((G42*I42)-K42-L42-M42,2) -> 203.77 | P42: =IF(D42=0,IF((N42-E42-O42)>0,(N42-E42-O42),0),IF((D42+N42-O42)>0,(D42+N42-O42),0)) -> 1129.51 | Q42: =IF(E42=0,IF((D42+N42-O42)<0,ABS(D42+N42-O42),0),IF((N42-E42-O42)<0,ABS(N42-E42-O42),0)) -> 0
...

Sheet лютий
A1: ОСББ "Карбишева - 22" | N1: 37465042
B2: Відомість нарахувань та оплати мешканців за утримання будинку
B3: у лютому 2023 року
A6: № кв. | B6: ПІБ | C6: Особ. рах. | D6: Д-Т | E6: К-Т | F6: Пільга % | G6: Заг.площа | H6: Пільг. Площа | I6: Внески | J6: 100% нарах. | K6: Пільгова сума | L6: сплачені суми пільг за реєстрами | M6: Коригування | N6: До сплати | O6: Сплачено | P6: Д-Т | Q6: К-Т
A7: 1 | B7: =січень!B7 -> Бережний В.М. | C7: =січень!C7 -> 1001 | D7: =січень!P7 -> 1314.7 | E7: =січень!Q7 -> 0 | F7: =січень!F7 -> 0 | G7: =січень!G7 -> 64.26 | H7: =січень!H7 -> 0 | I7: =січень!I7 -> 4.1 | J7: =ROUND(G7*I7,2) -> 263.47 | N7: =ROUND((G7*I7)-K7-L7-M7,2) -> 263.47 | P7: =IF(D7=0,IF((N7-E7-O7)>0,(N7-E7-O7),0),IF((D7+N7-O7)>0,(D7+N7-O7),0)) -> 1578.17 | Q7: =IF(E7=0,IF((D7+N7-O7)<0,ABS(D7+N7-O7),0),IF((N7-E7-O7)<0,ABS(N7-E7-O7),0)) -> 0
A8: 2 | B8: =січень!B8 -> Старикова Т.О. | C8: =січень!C8 -> 1002 | D8: =січень!P8 -> 2523.77 | E8: =січень!Q8 -> 0 | F8: =січень!F8 -> 0 | G8: =січень!G8 -> 48.71 | H8: =січень!H8 -> 0 | I8: =січень!I8 -> 4.1 | J8: =ROUND(G8*I8,2) -> 199.71 | N8: =ROUND((G8*I8)-K8-L8-M8,2) -> 199.71 | P8: =IF(D8=0,IF((N8-E8-O8)>0,(N8-E8-O8),0),IF((D8+N8-O8)>0,(D8+N8-O8),0)) -> 2723.48 | Q8: =IF(E8=0,IF((D8+N8-O8)<0,ABS(D8+N8-O8),0),IF((N8-E8-O8)<0,ABS(N8-E8-O8),0)) -> 0
A9: 3 | B9: =січень!B9 -> Мазур Т.В. | C9: =січень!C9 -> 1003 | D9: =січень!P9 -> 281 | E9: =січень!Q9 -> 0 | F9: =січень!F9 -> 0 | G9: =січень!G9 -> 35 | H9: =січень!H9 -> 0 | I9: =січень!I9 -> 4.1 | J9: =ROUND(G9*I9,2) -> 143.5 | N9: =ROUND((G9*I9)-K9-L9-M9,2) -> 143.5 | O9: 400 | P9: =IF(D9=0,IF((N9-E9-O9)>0,(N9-E9-O9),0),IF((D9+N9-O9)>0,(D9+N9-O9),0)) -> 24.5 | Q9: =IF(E9=0,IF((D9+N9-O9)<0,ABS(D9+N9-O9),0),IF((N9-E9-O9)<0,ABS(N9-E9-O9),0)) -> 0
A10: 4 | B10: =січень!B10 -> Сокол О.В. | C10: =січень!C10 -> 1004 | D10: =січень!P10 -> 0 | E10: =січень!Q10 -> 0.03 | F10: =січень!F10 -> 0 | G10: =січень!G10 -> 61.6 | H10: =січень!H10 -> 0 | I10: =січень!I10 -> 4.1 | J10: =ROUND(G10*I10,2) -> 252.56 | N10: =ROUND((G10*I10)-K10-L10-M10,2) -> 252.56 | O10: =252.56+252.56 -> 505.12 | P10: =IF(D10=0,IF((N10-E10-O10)>0,(N10-E10-O10),0),IF((D10+N10-O10)>0,(D10+N10-O10),0)) -> 0 | Q10: =IF(E10=0,IF((D10+N10-O10)<0,ABS(D10+N10-O10),0),IF((N10-E10-O10)<0,ABS(N10-E10-O10),0)) -> 252.59
A11: 5 | B11: =січень!B11 -> Семко Л.І. | C11: =січень!C11 -> 1005 | D11: =січень!P11 -> 277.22 | E11: =січень!Q11 -> 0 | F11: =січень!F11 -> 0 | G11: =січень!G11 -> 28.34 | H11: =січень!H11 -> 0 | I11: =січень!I11 -> 4.1 | J11: =ROUND(G11*I11,2) -> 116.19 | N11: =ROUND((G11*I11)-K11-L11-M11,2) -> 116.19 | P11: =IF(D11=0,IF((N11-E11-O11)>0,(N11-E11-O11),0),IF((D11+N11-O11)>0,(D11+N11-O11),0)) -> 393.41 | Q11: =IF(E11=0,IF((D11+N11-O11)<0,ABS(D11+N11-O11),0),IF((N11-E11-O11)<0,ABS(N11-E11-O11),0)) -> 0
A12: 5 | B12: =січень!B12 -> Гаркуша Н.І. | C12: =січень!C12 -> 1005-а | D12: =січень!P12 -> 248.41 | E12: =січень!Q12 -> 0 | F12: =січень!F12 -> 0 | G12: =січень!G12 -> 36.66 | H12: =січень!H12 -> 0 | I12: =січень!I12 -> 4.1 | J12: =ROUND(G12*I12,2) -> 150.31 | N12: =ROUND((G12*I12)-K12-L12-M12,2) -> 150.31 | O12: 500 | P12: =IF(D12=0,IF((N12-E12-O12)>0,(N12-E12-O12),0),IF((D12+N12-O12)>0,(D12+N12-O12),0)) -> 0 | Q12: =IF(E12=0,IF((D12+N12-O12)<0,ABS(D12+N12-O12),0),IF((N12-E12-O12)<0,ABS(N12-E12-O12),0)) -> 101.28
A13: 6 | B13: =січень!B13 -> Андріяшев В.М | C13: =січень!C13 -> 1006 | D13: =січень!P13 -> 1468.26 | E13: =січень!Q13 -> 0 | F13: =січень!F13 -> 0 | G13: =січень!G13 -> 49.8 | H13: =січень!H13 -> 0 | I13: =січень!I13 -> 4.1 | J13: =ROUND(G13*I13,2) -> 204.18 | N13: =ROUND((G13*I13)-K13-L13-M13,2) -> 204.18 | O13: 1025 | P13: =IF(D13=0,IF((N13-E13-O13)>0,(N13-E13-O13),0),IF((D13+N13-O13)>0,(D13+N13-O13),0)) -> 647.44 | Q13: =IF(E13=0,IF((D13+N13-O13)<0,ABS(D13+N13-O13),0),IF((N13-E13-O13)<0,ABS(N13-E13-O13),0)) -> 0
A14: 7 | B14: =січень!B14 -> Старчикова О.М. | C14: =січень!C14 -> 1007 | D14: =січень!P14 -> 0 | E14: =січень!Q14 -> 1.09 | F14: =січень!F14 -> 0 | G14: =січень!G14 -> 34.65 | H14: =січень!H14 -> 0 | I14: =січень!I14 -> 4.1 | J14: =ROUND(G14*I14,2) -> 142.07 | N14: =ROUND((G14*I14)-K14-L14-M14,2) -> 142.07 | P14: =IF(D14=0,IF((N14-E14-O14)>0,(N14-E14-O14),0),IF((D14+N14-O14)>0,(D14+N14-O14),0)) -> 140.98 | Q14: =IF(E14=0,IF((D14+N14-O14)<0,ABS(D14+N14-O14),0),IF((N14-E14-O14)<0,ABS(N14-E14-O14),0)) -> 0
A15: 8 | B15: =січень!B15 -> Безер Т.М | C15: =січень!C15 -> 1008 | D15: =січень!P15 -> 226.02 | E15: =січень!Q15 -> 0 | F15: =січень!F15 -> 0 | G15: =січень!G15 -> 62.14 | H15: =січень!H15 -> 0 | I15: =січень!I15 -> 4.1 | J15: =ROUND(G15*I15,2) -> 254.77 | N15: =ROUND((G15*I15)-K15-L15-M15,2) -> 254.77 | P15: =IF(D15=0,IF((N15-E15-O15)>0,(N15-E15-O15),0),IF((D15+N15-O15)>0,(D15+N15-O15),0)) -> 480.79 | Q15: =IF(E15=0,IF((D15+N15-O15)<0,ABS(D15+N15-O15),0),IF((N15-E15-O15)<0,ABS(N15-E15-O15),0)) -> 0
A16: 9 | B16: =січень!B16 -> Решетило М.М | C16: =січень!C16 -> 1009 | D16: =січень!P16 -> 3173.12 | E16: =січень!Q16 -> 0 | F16: =січень!F16 -> 0 | G16: =січень!G16 -> 65.16 | H16: =січень!H16 -> 0 | I16: =січень!I16 -> 4.1 | J16: =ROUND(G16*I16,2) -> 267.16 | N16: =ROUND((G16*I16)-K16-L16-M16,2) -> 267.16 | P16: =IF(D16=0,IF((N16-E16-O16)>0,(N16-E16-O16),0),IF((D16+N16-O16)>0,(D16+N16-O16),0)) -> 3440.28 | Q16: =IF(E16=0,IF((D16+N16-O16)<0,ABS(D16+N16-O16),0),IF((N16-E16-O16)<0,ABS(N16-E16-O16),0)) -> 0
A17: 10 | B17: =січень!B17 -> Фесенко О.В. | C17: =січень!C17 -> 1010 | D17: =січень!P17 -> 1787.34 | E17: =січень!Q17 -> 0 | F17: =січень!F17 -> 0 | G17: =січень!G17 -> 50.1 | H17: =січень!H17 -> 0 | I17: =січень!I17 -> 4.1 | J17: =ROUND(G17*I17,2) -> 205.41 | N17: =ROUND((G17*I17)-K17-L17-M17,2) -> 205.41 | P17: =IF(D17=0,IF((N17-E17-O17)>0,(N17-E17-O17),0),IF((D17+N17-O17)>0,(D17+N17-O17),0)) -> 1992.75 | Q17: =IF(E17=0,IF((D17+N17-O17)<0,ABS(D17+N17-O17),0),IF((N17-E17-O17)<0,ABS(N17-E17-O17),0)) -> 0
A18: 11 | B18: =січень!B18 -> Петренко О.М. | C18: =січень!C18 -> 1011 | D18: =січень!P18 -> 1497 | E18: =січень!Q18 -> 0 | F18: =січень!F18 -> 0 | G18: =січень!G18 -> 35.2 | H18: =січень!H18 -> 0 | I18: =січень!I18 -> 4.1 | J18: =ROUND(G18*I18,2) -> 144.32 | N18: =ROUND((G18*I18)-K18-L18-M18,2) -> 144.32 | P18: =IF(D18=0,IF((N18-E18-O18)>0,(N18-E18-O18),0),IF((D18+N18-O18)>0,(D18+N18-O18),0)) -> 1641.32 | Q18: =IF(E18=0,IF((D18+N18-O18)<0,ABS(D18+N18-O18),0),IF((N18-E18-O18)<0,ABS(N18-E18-O18),0)) -> 0
A19: 12 | B19: =січень!B19 -> Зеленюк А.Д | C19: =січень!C19 -> 1012 | D19: =січень!P19 -> 3170.61 | E19: =січень!Q19 -> 0 | F19: =січень!F19 -> 0 | G19: =січень!G19 -> 62.78 | H19: =січень!H19 -> 0 | I19: =січень!I19 -> 4.1 | J19: =ROUND(G19*I19,2) -> 257.4 | N19: =ROUND((G19*I19)-K19-L19-M19,2) -> 257.4 | P19: =IF(D19=0,IF((N19-E19-O19)>0,(N19-E19-O19),0),IF((D19+N19-O19)>0,(D19+N19-O19),0)) -> 3428.01 | Q19: =IF(E19=0,IF((D19+N19-O19)<0,ABS(D19+N19-O19),0),IF((N19-E19-O19)<0,ABS(N19-E19-O19),0)) -> 0
A20: 13 | B20: =січень!B20 -> Вовк І.В | C20: =січень!C20 -> 1013 | D20: =січень!P20 -> 2252.61 | E20: =січень!Q20 -> 0 | F20: =січень!F20 -> 0 | G20: =січень!G20 -> 28.23 | H20: =січень!H20 -> 0 | I20: =січень!I20 -> 4.1 | J20: =ROUND(G20*I20,2) -> 115.74 | N20: =ROUND((G20*I20)-K20-L20-M20,2) -> 115.74 | P20: =IF(D20=0,IF((N20-E20-O20)>0,(N20-E20-O20),0),IF((D20+N20-O20)>0,(D20+N20-O20),0)) -> 2368.35 | Q20: =IF(E20=0,IF((D20+N20-O20)<0,ABS(D20+N20-O20),0),IF((N20-E20-O20)<0,ABS(N20-E20-O20),0)) -> 0
A21: 13 | B21: =січень!B21 -> Романовський В.М | C21: =січень!C21 -> 1013-а | D21: =січень!P21 -> 3413.04 | E21: =січень!Q21 -> 0 | F21: =січень!F21 -> 0 | G21: =січень!G21 -> 37.84 | H21: =січень!H21 -> 0 | I21: =січень!I21 -> 4.1 | J21: =ROUND(G21*I21,2) -> 155.14 | N21: =ROUND((G21*I21)-K21-L21-M21,2) -> 155.14 | P21: =IF(D21=0,IF((N21-E21-O21)>0,(N21-E21-O21),0),IF((D21+N21-O21)>0,(D21+N21-O21),0)) -> 3568.18 | Q21: =IF(E21=0,IF((D21+N21-O21)<0,ABS(D21+N21-O21),0),IF((N21-E21-O21)<0,ABS(N21-E21-O21),0)) -> 0
A22: 14 | B22: =січень!B22 -> Ряба Л.І | C22: =січень!C22 -> 1014 | D22: =січень!P22 -> 913.16 | E22: =січень!Q22 -> 0 | F22: =січень!F22 -> 0 | G22: =січень!G22 -> 49.24 | H22: =січень!H22 -> 0 | I22: =січень!I22 -> 4.1 | J22: =ROUND(G22*I22,2) -> 201.88 | N22: =ROUND((G22*I22)-K22-L22-M22,2) -> 201.88 | P22: =IF(D22=0,IF((N22-E22-O22)>0,(N22-E22-O22),0),IF((D22+N22-O22)>0,(D22+N22-O22),0)) -> 1115.04 | Q22: =IF(E22=0,IF((D22+N22-O22)<0,ABS(D22+N22-O22),0),IF((N22-E22-O22)<0,ABS(N22-E22-O22),0)) -> 0
A23: 15 | B23: =січень!B23 -> Кас'янова О.А. | C23: =січень!C23 -> 1015 | D23: =січень!P23 -> 1052.95 | E23: =січень!Q23 -> 0 | F23: =січень!F23 -> 0 | G23: =січень!G23 -> 35.1 | H23: =січень!H23 -> 0 | I23: =січень!I23 -> 4.1 | J23: =ROUND(G23*I23,2) -> 143.91 | N23: =ROUND((G23*I23)-K23-L23-M23,2) -> 143.91 | P23: =IF(D23=0,IF((N23-E23-O23)>0,(N23-E23-O23),0),IF((D23+N23-O23)>0,(D23+N23-O23),0)) -> 1196.86 | Q23: =IF(E23=0,IF((D23+N23-O23)<0,ABS(D23+N23-O23),0),IF((N23-E23-O23)<0,ABS(N23-E23-O23),0)) -> 0
A24: 16 | B24: =січень!B24 -> Корякіна М.В. | C24: =січень!C24 -> 1016 | D24: =січень!P24 -> 1606.2 | E24: =січень!Q24 -> 0 | F24: =січень!F24 -> 0 | G24: =січень!G24 -> 61.9 | H24: =січень!H24 -> 0 | I24: =січень!I24 -> 4.1 | J24: =ROUND(G24*I24,2) -> 253.79 | N24: =ROUND((G24*I24)-K24-L24-M24,2) -> 253.79 | P24: =IF(D24=0,IF((N24-E24-O24)>0,(N24-E24-O24),0),IF((D24+N24-O24)>0,(D24+N24-O24),0)) -> 1859.99 | Q24: =IF(E24=0,IF((D24+N24-O24)<0,ABS(D24+N24-O24),0),IF((N24-E24-O24)<0,ABS(N24-E24-O24),0)) -> 0
A25: 17 | B25: =січень!B25 -> Сокерчак А.В. | C25: =січень!C25 -> 1017 | D25: =січень!P25 -> 271.83 | E25: =січень!Q25 -> 0 | F25: =січень!F25 -> 0 | G25: =січень!G25 -> 66.3 | H25: =січень!H25 -> 0 | I25: =січень!I25 -> 4.1 | J25: =ROUND(G25*I25,2) -> 271.83 | N25: =ROUND((G25*I25)-K25-L25-M25,2) -> 271.83 | O25: 815.49 | P25: =IF(D25=0,IF((N25-E25-O25)>0,(N25-E25-O25),0),IF((D25+N25-O25)>0,(D25+N25-O25),0)) -> 0 | Q25: =IF(E25=0,IF((D25+N25-O25)<0,ABS(D25+N25-O25),0),IF((N25-E25-O25)<0,ABS(N25-E25-O25),0)) -> 271.83
A26: 18 | B26: =січень!B26 -> Кравченко В.А | C26: =січень!C26 -> 1018 | D26: =січень!P26 -> 0 | E26: =січень!Q26 -> 1406.07 | F26: =січень!F26 -> 0 | G26: =січень!G26 -> 51.48 | H26: =січень!H26 -> 0 | I26: =січень!I26 -> 4.1 | J26: =ROUND(G26*I26,2) -> 211.07 | L26: 211.07 | N26: =ROUND((G26*I26)-K26-L26-M26,2) -> 0 | P26: =IF(D26=0,IF((N26-E26-O26)>0,(N26-E26-O26),0),IF((D26+N26-O26)>0,(D26+N26-O26),0)) -> 0 | Q26: =IF(E26=0,IF((D26+N26-O26)<0,ABS(D26+N26-O26),0),IF((N26-E26-O26)<0,ABS(N26-E26-O26),0)) -> 1406.07
A27: 19 | B27: =січень!B27 -> Чичикало А.С | C27: =січень!C27 -> 1019 | D27: =січень!P27 -> 142.29 | E27: =січень!Q27 -> 0 | F27: =січень!F27 -> 0 | G27: =січень!G27 -> 35.1 | H27: =січень!H27 -> 0 | I27: =січень!I27 -> 4.1 | J27: =ROUND(G27*I27,2) -> 143.91 | N27: =ROUND((G27*I27)-K27-L27-M27,2) -> 143.91 | P27: =IF(D27=0,IF((N27-E27-O27)>0,(N27-E27-O27),0),IF((D27+N27-O27)>0,(D27+N27-O27),0)) -> 286.2 | Q27: =IF(E27=0,IF((D27+N27-O27)<0,ABS(D27+N27-O27),0),IF((N27-E27-O27)<0,ABS(N27-E27-O27),0)) -> 0
A28: 20 | B28: =січень!B28 -> Сільващук А.А | C28: =січень!C28 -> 1020 | D28: =січень!P28 -> 257.07 | E28: =січень!Q28 -> 0 | F28: =січень!F28 -> 0 | G28: =січень!G28 -> 62.7 | H28: =січень!H28 -> 0 | I28: =січень!I28 -> 4.1 | J28: =ROUND(G28*I28,2) -> 257.07 | N28: =ROUND((G28*I28)-K28-L28-M28,2) -> 257.07 | O28: 1285.35 | P28: =IF(D28=0,IF((N28-E28-O28)>0,(N28-E28-O28),0),IF((D28+N28-O28)>0,(D28+N28-O28),0)) -> 0 | Q28: =IF(E28=0,IF((D28+N28-O28)<0,ABS(D28+N28-O28),0),IF((N28-E28-O28)<0,ABS(N28-E28-O28),0)) -> 771.21
A29: 21 | B29: =січень!B29 -> Стеценко Г.М | C29: =січень!C29 -> 1021 | D29: =січень!P29 -> 1971.54 | E29: =січень!Q29 -> 0 | F29: =січень!F29 -> 0 | G29: =січень!G29 -> 65.32 | H29: =січень!H29 -> 0 | I29: =січень!I29 -> 4.1 | J29: =ROUND(G29*I29,2) -> 267.81 | N29: =ROUND((G29*I29)-K29-L29-M29,2) -> 267.81 | O29: 500 | P29: =IF(D29=0,IF((N29-E29-O29)>0,(N29-E29-O29),0),IF((D29+N29-O29)>0,(D29+N29-O29),0)) -> 1739.35 | Q29: =IF(E29=0,IF((D29+N29-O29)<0,ABS(D29+N29-O29),0),IF((N29-E29-O29)<0,ABS(N29-E29-O29),0)) -> 0
A30: 22 | B30: =січень!B30 -> Кирдячкіна П.А | C30: =січень!C30 -> 1022 | D30: =січень!P30 -> 1203.93 | E30: =січень!Q30 -> 0 | F30: =січень!F30 -> 0 | G30: =січень!G30 -> 49.7 | H30: =січень!H30 -> 0 | I30: =січень!I30 -> 4.1 | J30: =ROUND(G30*I30,2) -> 203.77 | N30: =ROUND((G30*I30)-K30-L30-M30,2) -> 203.77 | P30: =IF(D30=0,IF((N30-E30-O30)>0,(N30-E30-O30),0),IF((D30+N30-O30)>0,(D30+N30-O30),0)) -> 1407.7 | Q30: =IF(E30=0,IF((D30+N30-O30)<0,ABS(D30+N30-O30),0),IF((N30-E30-O30)<0,ABS(N30-E30-O30),0)) -> 0
A31: 23 | B31: =січень!B31 -> Фоміченко Л.А | C31: =січень!C31 -> 1023 | D31: =січень!P31 -> 143.91 | E31: =січень!Q31 -> 0 | F31: =січень!F31 -> 0 | G31: =січень!G31 -> 35.1 | H31: =січень!H31 -> 0 | I31: =січень!I31 -> 4.1 | J31: =ROUND(G31*I31,2) -> 143.91 | N31: =ROUND((G31*I31)-K31-L31-M31,2) -> 143.91 | P31: =IF(D31=0,IF((N31-E31-O31)>0,(N31-E31-O31),0),IF((D31+N31-O31)>0,(D31+N31-O31),0)) -> 287.82 | Q31: =IF(E31=0,IF((D31+N31-O31)<0,ABS(D31+N31-O31),0),IF((N31-E31-O31)<0,ABS(N31-E31-O31),0)) -> 0
A32: 24 | B32: =січень!B32 -> Сердюк А.Г | C32: =січень!C32 -> 1024 | D32: =січень!P32 -> 1884.08 | E32: =січень!Q32 -> 0 | F32: =січень!F32 -> 0 | G32: =січень!G32 -> 62.31 | H32: =січень!H32 -> 0 | I32: =січень!I32 -> 4.1 | J32: =ROUND(G32*I32,2) -> 255.47 | N32: =ROUND((G32*I32)-K32-L32-M32,2) -> 255.47 | O32: 500 | P32: =IF(D32=0,IF((N32-E32-O32)>0,(N32-E32-O32),0),IF((D32+N32-O32)>0,(D32+N32-O32),0)) -> 1639.55 | Q32: =IF(E32=0,IF((D32+N32-O32)<0,ABS(D32+N32-O32),0),IF((N32-E32-O32)<0,ABS(N32-E32-O32),0)) -> 0
A33: 25 | B33: =січень!B33 -> Михальченко Г.М | C33: =січень!C33 -> 1025 | D33: =січень!P33 -> 3054.14 | E33: =січень!Q33 -> 0 | F33: =січень!F33 -> 0 | G33: =січень!G33 -> 65.04 | H33: =січень!H33 -> 0 | I33: =січень!I33 -> 4.1 | J33: =ROUND(G33*I33,2) -> 266.66 | N33: =ROUND((G33*I33)-K33-L33-M33,2) -> 266.66 | P33: =IF(D33=0,IF((N33-E33-O33)>0,(N33-E33-O33),0),IF((D33+N33-O33)>0,(D33+N33-O33),0)) -> 3320.8 | Q33: =IF(E33=0,IF((D33+N33-O33)<0,ABS(D33+N33-O33),0),IF((N33-E33-O33)<0,ABS(N33-E33-O33),0)) -> 0
A34: 26 | B34: =січень!B34 -> Замуховська Я.С | C34: =січень!C34 -> 1026 | D34: =січень!P34 -> 1241.15 | E34: =січень!Q34 -> 0 | F34: =січень!F34 -> 0 | G34: =січень!G34 -> 49.8 | H34: =січень!H34 -> 0 | I34: =січень!I34 -> 4.1 | J34: =ROUND(G34*I34,2) -> 204.18 | N34: =ROUND((G34*I34)-K34-L34-M34,2) -> 204.18 | P34: =IF(D34=0,IF((N34-E34-O34)>0,(N34-E34-O34),0),IF((D34+N34-O34)>0,(D34+N34-O34),0)) -> 1445.33 | Q34: =IF(E34=0,IF((D34+N34-O34)<0,ABS(D34+N34-O34),0),IF((N34-E34-O34)<0,ABS(N34-E34-O34),0)) -> 0
A35: 27 | B35: =січень!B35 -> Мержиєвська Г.К | C35: =січень!C35 -> 1027 | D35: =січень!P35 -> 1063.1 | E35: =січень!Q35 -> 0 | F35: =січень!F35 -> 0 | G35: =січень!G35 -> 35.17 | H35: =січень!H35 -> 0 | I35: =січень!I35 -> 4.1 | J35: =ROUND(G35*I35,2) -> 144.2 | N35: =ROUND((G35*I35)-K35-L35-M35,2) -> 144.2 | O35: 500 | P35: =IF(D35=0,IF((N35-E35-O35)>0,(N35-E35-O35),0),IF((D35+N35-O35)>0,(D35+N35-O35),0)) -> 707.3 | Q35: =IF(E35=0,IF((D35+N35-O35)<0,ABS(D35+N35-O35),0),IF((N35-E35-O35)<0,ABS(N35-E35-O35),0)) -> 0
A36: 28 | B36: =січень!B36 -> Кулакова Л.В. | C36: =січень!C36 -> 1028 | D36: =січень!P36 -> 229.44 | E36: =січень!Q36 -> 0 | F36: =січень!F36 -> 0 | G36: =січень!G36 -> 62.47 | H36: =січень!H36 -> 0 | I36: =січень!I36 -> 4.1 | J36: =ROUND(G36*I36,2) -> 256.13 | N36: =ROUND((G36*I36)-K36-L36-M36,2) -> 256.13 | P36: =IF(D36=0,IF((N36-E36-O36)>0,(N36-E36-O36),0),IF((D36+N36-O36)>0,(D36+N36-O36),0)) -> 485.57 | Q36: =IF(E36=0,IF((D36+N36-O36)<0,ABS(D36+N36-O36),0),IF((N36-E36-O36)<0,ABS(N36-E36-O36),0)) -> 0
A37: 29 | B37: =січень!B37 -> Бочаров В.Л. | C37: =січень!C37 -> 1029 | D37: =січень!P37 -> 1748.22 | E37: =січень!Q37 -> 0 | F37: =січень!F37 -> 0 | G37: =січень!G37 -> 65.75 | H37: =січень!H37 -> 0 | I37: =січень!I37 -> 4.1 | J37: =ROUND(G37*I37,2) -> 269.58 | N37: =ROUND((G37*I37)-K37-L37-M37,2) -> 269.58 | P37: =IF(D37=0,IF((N37-E37-O37)>0,(N37-E37-O37),0),IF((D37+N37-O37)>0,(D37+N37-O37),0)) -> 2017.8 | Q37: =IF(E37=0,IF((D37+N37-O37)<0,ABS(D37+N37-O37),0),IF((N37-E37-O37)<0,ABS(N37-E37-O37),0)) -> 0
A38: 30 | B38: =січень!B38 -> Лучков В.Л. | C38: =січень!C38 -> 1030 | D38: =січень!P38 -> 2436.6 | E38: =січень!Q38 -> 0 | F38: =січень!F38 -> 0 | G38: =січень!G38 -> 49.7 | H38: =січень!H38 -> 0 | I38: =січень!I38 -> 4.1 | J38: =ROUND(G38*I38,2) -> 203.77 | N38: =ROUND((G38*I38)-K38-L38-M38,2) -> 203.77 | P38: =IF(D38=0,IF((N38-E38-O38)>0,(N38-E38-O38),0),IF((D38+N38-O38)>0,(D38+N38-O38),0)) -> 2640.37 | Q38: =IF(E38=0,IF((D38+N38-O38)<0,ABS(D38+N38-O38),0),IF((N38-E38-O38)<0,ABS(N38-E38-O38),0)) -> 0
A39: 31 | B39: =січень!B39 -> Кашкар Т.М. | C39: =січень!C39 -> 1031 | D39: =січень!P39 -> 0 | E39: =січень!Q39 -> 5.6843419e-14 | F39: =січень!F39 -> 0 | G39: =січень!G39 -> 35.1 | H39: =січень!H39 -> 0 | I39: =січень!I39 -> 4.1 | J39: =ROUND(G39*I39,2) -> 143.91 | N39: =ROUND((G39*I39)-K39-L39-M39,2) -> 143.91 | O39: 143.91 | P39: =IF(D39=0,IF((N39-E39-O39)>0,(N39-E39-O39),0),IF((D39+N39-O39)>0,(D39+N39-O39),0)) -> 0 | Q39: =IF(E39=0,IF((D39+N39-O39)<0,ABS(D39+N39-O39),0),IF((N39-E39-O39)<0,ABS(N39-E39-O39),0)) -> 0
A40: 32 | B40: =січень!B40 -> Стецюк Н.П. | C40: =січень!C40 -> 1032 | D40: =січень!P40 -> 2013.46 | E40: =січень!Q40 -> 0 | F40: =січень!F40 -> 0 | G40: =січень!G40 -> 61.9 | H40: =січень!H40 -> 0 | I40: =січень!I40 -> 4.1 | J40: =ROUND(G40*I40,2) -> 253.79 | N40: =ROUND((G40*I40)-K40-L40-M40,2) -> 253.79 | P40: =IF(D40=0,IF((N40-E40-O40)>0,(N40-E40-O40),0),IF((D40+N40-O40)>0,(D40+N40-O40),0)) -> 2267.25 | Q40: =IF(E40=0,IF((D40+N40-O40)<0,ABS(D40+N40-O40),0),IF((N40-E40-O40)<0,ABS(N40-E40-O40),0)) -> 0
A41: 33 | B41: =січень!B41 -> Маханько В.О. | C41: =січень!C41 -> 1033 | D41: =січень!P41 -> 1232.64 | E41: =січень!Q41 -> 0 | F41: =січень!F41 -> 0 | G41: =січень!G41 -> 65.53 | H41: =січень!H41 -> 0 | I41: =січень!I41 -> 4.1 | J41: =ROUND(G41*I41,2) -> 268.67 | L41: 268.67 | N41: =ROUND((G41*I41)-K41-L41-M41,2) -> 0 | P41: =IF(D41=0,IF((N41-E41-O41)>0,(N41-E41-O41),0),IF((D41+N41-O41)>0,(D41+N41-O41),0)) -> 1232.64 | Q41: =IF(E41=0,IF((D41+N41-O41)<0,ABS(D41+N41-O41),0),IF((N41-E41-O41)<0,ABS(N41-E41-O41),0)) -> 0
A42: 34 | B42: =січень!B42 -> Реуцька Р.С. | C42: =січень!C42 -> 1034 | D42: =січень!P42 -> 1129.51 | E42: =січень!Q42 -> 0 | F42: =січень!F42 -> 0 | G42: =січень!G42 -> 49.7 | H42: =січень!H42 -> 0 | I42: =січень!I42 -> 4.1 | J42: =ROUND(G42*I42,2) -> 203.77 | N42: =ROUND((G42*I42)-K42-L42-M42,2) -> 203.77 | P42: =IF(D42=0,IF((N42-E42-O42)>0,(N42-E42-O42),0),IF((D42+N42-O42)>0,(D42+N42-O42),0)) -> 1333.28 | Q42: =IF(E42=0,IF((D42+N42-O42)<0,ABS(D42+N42-O42),0),IF((N42-E42-O42)<0,ABS(N42-E42-O42),0)) -> 0
...

Sheet березень
A1: ОСББ "Карбишева - 22" | N1: 37465042
B2: Відомість нарахувань та оплати мешканців за утримання будинку
B3: у березні 2023 року
A6: № кв. | B6: ПІБ | C6: Особ. рах. | D6: Д-Т | E6: К-Т | F6: Пільга % | G6: Заг.площа | H6: Пільг. Площа | I6: Внески | J6: 100% нарах. | K6: Пільгова сума | L6: сплачені суми пільг за реєстрами | M6: Коригування | N6: До сплати | O6: Сплачено | P6: Д-Т | Q6: К-Т
A7: 1 | B7: =лютий!B7 -> Бережний В.М. | C7: =лютий!C7 -> 1001 | D7: =лютий!P7 -> 1578.17 | E7: =лютий!Q7 -> 0 | F7: =лютий!F7 -> 0 | G7: =лютий!G7 -> 64.26 | H7: =лютий!H7 -> 0 | I7: =лютий!I7 -> 4.1 | J7: =ROUND(G7*I7,2) -> 263.47 | N7: =ROUND((G7*I7)-K7-L7-M7,2) -> 263.47 | P7: =IF(D7=0,IF((N7-E7-O7)>0,(N7-E7-O7),0),IF((D7+N7-O7)>0,(D7+N7-O7),0)) -> 1841.64 | Q7: =IF(E7=0,IF((D7+N7-O7)<0,ABS(D7+N7-O7),0),IF((N7-E7-O7)<0,ABS(N7-E7-O7),0)) -> 0
A8: 2 | B8: =лютий!B8 -> Старикова Т.О. | C8: =лютий!C8 -> 1002 | D8: =лютий!P8 -> 2723.48 | E8: =лютий!Q8 -> 0 | F8: =лютий!F8 -> 0 | G8: =лютий!G8 -> 48.71 | H8: =лютий!H8 -> 0 | I8: =лютий!I8 -> 4.1 | J8: =ROUND(G8*I8,2) -> 199.71 | N8: =ROUND((G8*I8)-K8-L8-M8,2) -> 199.71 | P8: =IF(D8=0,IF((N8-E8-O8)>0,(N8-E8-O8),0),IF((D8+N8-O8)>0,(D8+N8-O8),0)) -> 2923.19 | Q8: =IF(E8=0,IF((D8+N8-O8)<0,ABS(D8+N8-O8),0),IF((N8-E8-O8)<0,ABS(N8-E8-O8),0)) -> 0
A9: 3 | B9: =лютий!B9 -> Мазур Т.В. | C9: =лютий!C9 -> 1003 | D9: =лютий!P9 -> 24.5 | E9: =лютий!Q9 -> 0 | F9: =лютий!F9 -> 0 | G9: =лютий!G9 -> 35 | H9: =лютий!H9 -> 0 | I9: =лютий!I9 -> 4.1 | J9: =ROUND(G9*I9,2) -> 143.5 | N9: =ROUND((G9*I9)-K9-L9-M9,2) -> 143.5 | P9: =IF(D9=0,IF((N9-E9-O9)>0,(N9-E9-O9),0),IF((D9+N9-O9)>0,(D9+N9-O9),0)) -> 168 | Q9: =IF(E9=0,IF((D9+N9-O9)<0,ABS(D9+N9-O9),0),IF((N9-E9-O9)<0,ABS(N9-E9-O9),0)) -> 0
A10: 4 | B10: =лютий!B10 -> Сокол О.В. | C10: =лютий!C10 -> 1004 | D10: =лютий!P10 -> 0 | E10: =лютий!Q10 -> 252.59 | F10: =лютий!F10 -> 0 | G10: =лютий!G10 -> 61.6 | H10: =лютий!H10 -> 0 | I10: =лютий!I10 -> 4.1 | J10: =ROUND(G10*I10,2) -> 252.56 | N10: =ROUND((G10*I10)-K10-L10-M10,2) -> 252.56 | P10: =IF(D10=0,IF((N10-E10-O10)>0,(N10-E10-O10),0),IF((D10+N10-O10)>0,(D10+N10-O10),0)) -> 0 | Q10: =IF(E10=0,IF((D10+N10-O10)<0,ABS(D10+N10-O10),0),IF((N10-E10-O10)<0,ABS(N10-E10-O10),0)) -> 0.03
A11: 5 | B11: =лютий!B11 -> Семко Л.І. | C11: =лютий!C11 -> 1005 | D11: =лютий!P11 -> 393.41 | E11: =лютий!Q11 -> 0 | F11: =лютий!F11 -> 0 | G11: =лютий!G11 -> 28.34 | H11: =лютий!H11 -> 0 | I11: =лютий!I11 -> 4.1 | J11: =ROUND(G11*I11,2) -> 116.19 | N11: =ROUND((G11*I11)-K11-L11-M11,2) -> 116.19 | O11: 1000 | P11: =IF(D11=0,IF((N11-E11-O11)>0,(N11-E11-O11),0),IF((D11+N11-O11)>0,(D11+N11-O11),0)) -> 0 | Q11: =IF(E11=0,IF((D11+N11-O11)<0,ABS(D11+N11-O11),0),IF((N11-E11-O11)<0,ABS(N11-E11-O11),0)) -> 490.4
A12: 5 | B12: =лютий!B12 -> Гаркуша Н.І. | C12: =лютий!C12 -> 1005-а | D12: =лютий!P12 -> 0 | E12: =лютий!Q12 -> 101.28 | F12: =лютий!F12 -> 0 | G12: =лютий!G12 -> 36.66 | H12: =лютий!H12 -> 0 | I12: =лютий!I12 -> 4.1 | J12: =ROUND(G12*I12,2) -> 150.31 | N12: =ROUND((G12*I12)-K12-L12-M12,2) -> 150.31 | O12: 300 | P12: =IF(D12=0,IF((N12-E12-O12)>0,(N12-E12-O12),0),IF((D12+N12-O12)>0,(D12+N12-O12),0)) -> 0 | Q12: =IF(E12=0,IF((D12+N12-O12)<0,ABS(D12+N12-O12),0),IF((N12-E12-O12)<0,ABS(N12-E12-O12),0)) -> 250.97
A13: 6 | B13: =лютий!B13 -> Андріяшев В.М | C13: =лютий!C13 -> 1006 | D13: =лютий!P13 -> 647.44 | E13: =лютий!Q13 -> 0 | F13: =лютий!F13 -> 0 | G13: =лютий!G13 -> 49.8 | H13: =лютий!H13 -> 0 | I13: =лютий!I13 -> 4.1 | J13: =ROUND(G13*I13,2) -> 204.18 | N13: =ROUND((G13*I13)-K13-L13-M13,2) -> 204.18 | O13: 1025 | P13: =IF(D13=0,IF((N13-E13-O13)>0,(N13-E13-O13),0),IF((D13+N13-O13)>0,(D13+N13-O13),0)) -> 0 | Q13: =IF(E13=0,IF((D13+N13-O13)<0,ABS(D13+N13-O13),0),IF((N13-E13-O13)<0,ABS(N13-E13-O13),0)) -> 173.38
A14: 7 | B14: =лютий!B14 -> Старчикова О.М. | C14: =лютий!C14 -> 1007 | D14: =лютий!P14 -> 140.98 | E14: =лютий!Q14 -> 0 | F14: =лютий!F14 -> 0 | G14: =лютий!G14 -> 34.65 | H14: =лютий!H14 -> 0 | I14: =лютий!I14 -> 4.1 | J14: =ROUND(G14*I14,2) -> 142.07 | N14: =ROUND((G14*I14)-K14-L14-M14,2) -> 142.07 | O14: 143 | P14: =IF(D14=0,IF((N14-E14-O14)>0,(N14-E14-O14),0),IF((D14+N14-O14)>0,(D14+N14-O14),0)) -> 140.05 | Q14: =IF(E14=0,IF((D14+N14-O14)<0,ABS(D14+N14-O14),0),IF((N14-E14-O14)<0,ABS(N14-E14-O14),0)) -> 0
A15: 8 | B15: =лютий!B15 -> Безер Т.М | C15: =лютий!C15 -> 1008 | D15: =лютий!P15 -> 480.79 | E15: =лютий!Q15 -> 0 | F15: =лютий!F15 -> 0 | G15: =лютий!G15 -> 62.14 | H15: =лютий!H15 -> 0 | I15: =лютий!I15 -> 4.1 | J15: =ROUND(G15*I15,2) -> 254.77 | N15: =ROUND((G15*I15)-K15-L15-M15,2) -> 254.77 | P15: =IF(D15=0,IF((N15-E15-O15)>0,(N15-E15-O15),0),IF((D15+N15-O15)>0,(D15+N15-O15),0)) -> 735.56 | Q15: =IF(E15=0,IF((D15+N15-O15)<0,ABS(D15+N15-O15),0),IF((N15-E15-O15)<0,ABS(N15-E15-O15),0)) -> 0
A16: 9 | B16: =лютий!B16 -> Решетило М.М | C16: =лютий!C16 -> 1009 | D16: =лютий!P16 -> 3440.28 | E16: =лютий!Q16 -> 0 | F16: =лютий!F16 -> 0 | G16: =лютий!G16 -> 65.16 | H16: =лютий!H16 -> 0 | I16: =лютий!I16 -> 4.1 | J16: =ROUND(G16*I16,2) -> 267.16 | N16: =ROUND((G16*I16)-K16-L16-M16,2) -> 267.16 | P16: =IF(D16=0,IF((N16-E16-O16)>0,(N16-E16-O16),0),IF((D16+N16-O16)>0,(D16+N16-O16),0)) -> 3707.44 | Q16: =IF(E16=0,IF((D16+N16-O16)<0,ABS(D16+N16-O16),0),IF((N16-E16-O16)<0,ABS(N16-E16-O16),0)) -> 0
A17: 10 | B17: =лютий!B17 -> Фесенко О.В. | C17: =лютий!C17 -> 1010 | D17: =лютий!P17 -> 1992.75 | E17: =лютий!Q17 -> 0 | F17: =лютий!F17 -> 0 | G17: =лютий!G17 -> 50.1 | H17: =лютий!H17 -> 0 | I17: =лютий!I17 -> 4.1 | J17: =ROUND(G17*I17,2) -> 205.41 | N17: =ROUND((G17*I17)-K17-L17-M17,2) -> 205.41 | P17: =IF(D17=0,IF((N17-E17-O17)>0,(N17-E17-O17),0),IF((D17+N17-O17)>0,(D17+N17-O17),0)) -> 2198.16 | Q17: =IF(E17=0,IF((D17+N17-O17)<0,ABS(D17+N17-O17),0),IF((N17-E17-O17)<0,ABS(N17-E17-O17),0)) -> 0
A18: 11 | B18: =лютий!B18 -> Петренко О.М. | C18: =лютий!C18 -> 1011 | D18: =лютий!P18 -> 1641.32 | E18: =лютий!Q18 -> 0 | F18: =лютий!F18 -> 0 | G18: =лютий!G18 -> 35.2 | H18: =лютий!H18 -> 0 | I18: =лютий!I18 -> 4.1 | J18: =ROUND(G18*I18,2) -> 144.32 | N18: =ROUND((G18*I18)-K18-L18-M18,2) -> 144.32 | P18: =IF(D18=0,IF((N18-E18-O18)>0,(N18-E18-O18),0),IF((D18+N18-O18)>0,(D18+N18-O18),0)) -> 1785.64 | Q18: =IF(E18=0,IF((D18+N18-O18)<0,ABS(D18+N18-O18),0),IF((N18-E18-O18)<0,ABS(N18-E18-O18),0)) -> 0
A19: 12 | B19: =лютий!B19 -> Зеленюк А.Д | C19: =лютий!C19 -> 1012 | D19: =лютий!P19 -> 3428.01 | E19: =лютий!Q19 -> 0 | F19: =лютий!F19 -> 0 | G19: =лютий!G19 -> 62.78 | H19: =лютий!H19 -> 0 | I19: =лютий!I19 -> 4.1 | J19: =ROUND(G19*I19,2) -> 257.4 | N19: =ROUND((G19*I19)-K19-L19-M19,2) -> 257.4 | P19: =IF(D19=0,IF((N19-E19-O19)>0,(N19-E19-O19),0),IF((D19+N19-O19)>0,(D19+N19-O19),0)) -> 3685.41 | Q19: =IF(E19=0,IF((D19+N19-O19)<0,ABS(D19+N19-O19),0),IF((N19-E19-O19)<0,ABS(N19-E19-O19),0)) -> 0
A20: 13 | B20: =лютий!B20 -> Вовк І.В | C20: =лютий!C20 -> 1013 | D20: =лютий!P20 -> 2368.35 | E20: =лютий!Q20 -> 0 | F20: =лютий!F20 -> 0 | G20: =лютий!G20 -> 28.23 | H20: =лютий!H20 -> 0 | I20: =лютий!I20 -> 4.1 | J20: =ROUND(G20*I20,2) -> 115.74 | N20: =ROUND((G20*I20)-K20-L20-M20,2) -> 115.74 | P20: =IF(D20=0,IF((N20-E20-O20)>0,(N20-E20-O20),0),IF((D20+N20-O20)>0,(D20+N20-O20),0)) -> 2484.09 | Q20: =IF(E20=0,IF((D20+N20-O20)<0,ABS(D20+N20-O20),0),IF((N20-E20-O20)<0,ABS(N20-E20-O20),0)) -> 0
A21: 13 | B21: =лютий!B21 -> Романовський В.М | C21: =лютий!C21 -> 1013-а | D21: =лютий!P21 -> 3568.18 | E21: =лютий!Q21 -> 0 | F21: =лютий!F21 -> 0 | G21: =лютий!G21 -> 37.84 | H21: =лютий!H21 -> 0 | I21: =лютий!I21 -> 4.1 | J21: =ROUND(G21*I21,2) -> 155.14 | N21: =ROUND((G21*I21)-K21-L21-M21,2) -> 155.14 | P21: =IF(D21=0,IF((N21-E21-O21)>0,(N21-E21-O21),0),IF((D21+N21-O21)>0,(D21+N21-O21),0)) -> 3723.32 | Q21: =IF(E21=0,IF((D21+N21-O21)<0,ABS(D21+N21-O21),0),IF((N21-E21-O21)<0,ABS(N21-E21-O21),0)) -> 0
A22: 14 | B22: =лютий!B22 -> Ряба Л.І | C22: =лютий!C22 -> 1014 | D22: =лютий!P22 -> 1115.04 | E22: =лютий!Q22 -> 0 | F22: =лютий!F22 -> 0 | G22: =лютий!G22 -> 49.24 | H22: =лютий!H22 -> 0 | I22: =лютий!I22 -> 4.1 | J22: =ROUND(G22*I22,2) -> 201.88 | N22: =ROUND((G22*I22)-K22-L22-M22,2) -> 201.88 | O22: 700 | P22: =IF(D22=0,IF((N22-E22-O22)>0,(N22-E22-O22),0),IF((D22+N22-O22)>0,(D22+N22-O22),0)) -> 616.92 | Q22: =IF(E22=0,IF((D22+N22-O22)<0,ABS(D22+N22-O22),0),IF((N22-E22-O22)<0,ABS(N22-E22-O22),0)) -> 0
A23: 15 | B23: =лютий!B23 -> Кас'янова О.А. | C23: =лютий!C23 -> 1015 | D23: =лютий!P23 -> 1196.86 | E23: =лютий!Q23 -> 0 | F23: =лютий!F23 -> 0 | G23: =лютий!G23 -> 35.1 | H23: =лютий!H23 -> 0 | I23: =лютий!I23 -> 4.1 | J23: =ROUND(G23*I23,2) -> 143.91 | N23: =ROUND((G23*I23)-K23-L23-M23,2) -> 143.91 | P23: =IF(D23=0,IF((N23-E23-O23)>0,(N23-E23-O23),0),IF((D23+N23-O23)>0,(D23+N23-O23),0)) -> 1340.77 | Q23: =IF(E23=0,IF((D23+N23-O23)<0,ABS(D23+N23-O23),0),IF((N23-E23-O23)<0,ABS(N23-E23-O23),0)) -> 0
A24: 16 | B24: =лютий!B24 -> Корякіна М.В. | C24: =лютий!C24 -> 1016 | D24: =лютий!P24 -> 1859.99 | E24: =лютий!Q24 -> 0 | F24: =лютий!F24 -> 0 | G24: =лютий!G24 -> 61.9 | H24: =лютий!H24 -> 0 | I24: =лютий!I24 -> 4.1 | J24: =ROUND(G24*I24,2) -> 253.79 | N24: =ROUND((G24*I24)-K24-L24-M24,2) -> 253.79 | P24: =IF(D24=0,IF((N24-E24-O24)>0,(N24-E24-O24),0),IF((D24+N24-O24)>0,(D24+N24-O24),0)) -> 2113.78 | Q24: =IF(E24=0,IF((D24+N24-O24)<0,ABS(D24+N24-O24),0),IF((N24-E24-O24)<0,ABS(N24-E24-O24),0)) -> 0
A25: 17 | B25: =лютий!B25 -> Сокерчак А.В. | C25: =лютий!C25 -> 1017 | D25: =лютий!P25 -> 0 | E25: =лютий!Q25 -> 271.83 | F25: =лютий!F25 -> 0 | G25: =лютий!G25 -> 66.3 | H25: =лютий!H25 -> 0 | I25: =лютий!I25 -> 4.1 | J25: =ROUND(G25*I25,2) -> 271.83 | N25: =ROUND((G25*I25)-K25-L25-M25,2) -> 271.83 | P25: =IF(D25=0,IF((N25-E25-O25)>0,(N25-E25-O25),0),IF((D25+N25-O25)>0,(D25+N25-O25),0)) -> 0 | Q25: =IF(E25=0,IF((D25+N25-O25)<0,ABS(D25+N25-O25),0),IF((N25-E25-O25)<0,ABS(N25-E25-O25),0)) -> 1.080025e-12
A26: 18 | B26: =лютий!B26 -> Кравченко В.А | C26: =лютий!C26 -> 1018 | D26: =лютий!P26 -> 0 | E26: =лютий!Q26 -> 1406.07 | F26: =лютий!F26 -> 0 | G26: =лютий!G26 -> 51.48 | H26: =лютий!H26 -> 0 | I26: =лютий!I26 -> 4.1 | J26: =ROUND(G26*I26,2) -> 211.07 | N26: =ROUND((G26*I26)-K26-L26-M26,2) -> 211.07 | P26: =IF(D26=0,IF((N26-E26-O26)>0,(N26-E26-O26),0),IF((D26+N26-O26)>0,(D26+N26-O26),0)) -> 0 | Q26: =IF(E26=0,IF((D26+N26-O26)<0,ABS(D26+N26-O26),0),IF((N26-E26-O26)<0,ABS(N26-E26-O26),0)) -> 1195
A27: 19 | B27: =лютий!B27 -> Чичикало А.С | C27: =лютий!C27 -> 1019 | D27: =лютий!P27 -> 286.2 | E27: =лютий!Q27 -> 0 | F27: =лютий!F27 -> 0 | G27: =лютий!G27 -> 35.1 | H27: =лютий!H27 -> 0 | I27: =лютий!I27 -> 4.1 | J27: =ROUND(G27*I27,2) -> 143.91 | N27: =ROUND((G27*I27)-K27-L27-M27,2) -> 143.91 | P27: =IF(D27=0,IF((N27-E27-O27)>0,(N27-E27-O27),0),IF((D27+N27-O27)>0,(D27+N27-O27),0)) -> 430.11 | Q27: =IF(E27=0,IF((D27+N27-O27)<0,ABS(D27+N27-O27),0),IF((N27-E27-O27)<0,ABS(N27-E27-O27),0)) -> 0
A28: 20 | B28: =лютий!B28 -> Сільващук А.А | C28: =лютий!C28 -> 1020 | D28: =лютий!P28 -> 0 | E28: =лютий!Q28 -> 771.21 | F28: =лютий!F28 -> 0 | G28: =лютий!G28 -> 62.7 | H28: =лютий!H28 -> 0 | I28: =лютий!I28 -> 4.1 | J28: =ROUND(G28*I28,2) -> 257.07 | N28: =ROUND((G28*I28)-K28-L28-M28,2) -> 257.07 | P28: =IF(D28=0,IF((N28-E28-O28)>0,(N28-E28-O28),0),IF((D28+N28-O28)>0,(D28+N28-O28),0)) -> 0 | Q28: =IF(E28=0,IF((D28+N28-O28)<0,ABS(D28+N28-O28),0),IF((N28-E28-O28)<0,ABS(N28-E28-O28),0)) -> 514.14
A29: 21 | B29: =лютий!B29 -> Стеценко Г.М | C29: =лютий!C29 -> 1021 | D29: =лютий!P29 -> 1739.35 | E29: =лютий!Q29 -> 0 | F29: =лютий!F29 -> 0 | G29: =лютий!G29 -> 65.32 | H29: =лютий!H29 -> 0 | I29: =лютий!I29 -> 4.1 | J29: =ROUND(G29*I29,2) -> 267.81 | N29: =ROUND((G29*I29)-K29-L29-M29,2) -> 267.81 | O29: 300 | P29: =IF(D29=0,IF((N29-E29-O29)>0,(N29-E29-O29),0),IF((D29+N29-O29)>0,(D29+N29-O29),0)) -> 1707.16 | Q29: =IF(E29=0,IF((D29+N29-O29)<0,ABS(D29+N29-O29),0),IF((N29-E29-O29)<0,ABS(N29-E29-O29),0)) -> 0
A30: 22 | B30: =лютий!B30 -> Кирдячкіна П.А | C30: =лютий!C30 -> 1022 | D30: =лютий!P30 -> 1407.7 | E30: =лютий!Q30 -> 0 | F30: =лютий!F30 -> 0 | G30: =лютий!G30 -> 49.7 | H30: =лютий!H30 -> 0 | I30: =лютий!I30 -> 4.1 | J30: =ROUND(G30*I30,2) -> 203.77 | N30: =ROUND((G30*I30)-K30-L30-M30,2) -> 203.77 | O30: 500 | P30: =IF(D30=0,IF((N30-E30-O30)>0,(N30-E30-O30),0),IF((D30+N30-O30)>0,(D30+N30-O30),0)) -> 1111.47 | Q30: =IF(E30=0,IF((D30+N30-O30)<0,ABS(D30+N30-O30),0),IF((N30-E30-O30)<0,ABS(N30-E30-O30),0)) -> 0
A31: 23 | B31: =лютий!B31 -> Фоміченко Л.А | C31: =лютий!C31 -> 1023 | D31: =лютий!P31 -> 287.82 | E31: =лютий!Q31 -> 0 | F31: =лютий!F31 -> 0 | G31: =лютий!G31 -> 35.1 | H31: =лютий!H31 -> 0 | I31: =лютий!I31 -> 4.1 | J31: =ROUND(G31*I31,2) -> 143.91 | N31: =ROUND((G31*I31)-K31-L31-M31,2) -> 143.91 | P31: =IF(D31=0,IF((N31-E31-O31)>0,(N31-E31-O31),0),IF((D31+N31-O31)>0,(D31+N31-O31),0)) -> 431.73 | Q31: =IF(E31=0,IF((D31+N31-O31)<0,ABS(D31+N31-O31),0),IF((N31-E31-O31)<0,ABS(N31-E31-O31),0)) -> 0
A32: 24 | B32: =лютий!B32 -> Сердюк А.Г | C32: =лютий!C32 -> 1024 | D32: =лютий!P32 -> 1639.55 | E32: =лютий!Q32 -> 0 | F32: =лютий!F32 -> 0 | G32: =лютий!G32 -> 62.31 | H32: =лютий!H32 -> 0 | I32: =лютий!I32 -> 4.1 | J32: =ROUND(G32*I32,2) -> 255.47 | N32: =ROUND((G32*I32)-K32-L32-M32,2) -> 255.47 | O32: 300 | P32: =IF(D32=0,IF((N32-E32-O32)>0,(N32-E32-O32),0),IF((D32+N32-O32)>0,(D32+N32-O32),0)) -> 1595.02 | Q32: =IF(E32=0,IF((D32+N32-O32)<0,ABS(D32+N32-O32),0),IF((N32-E32-O32)<0,ABS(N32-E32-O32),0)) -> 0
A33: 25 | B33: =лютий!B33 -> Михальченко Г.М | C33: =лютий!C33 -> 1025 | D33: =лютий!P33 -> 3320.8 | E33: =лютий!Q33 -> 0 | F33: =лютий!F33 -> 0 | G33: =лютий!G33 -> 65.04 | H33: =лютий!H33 -> 0 | I33: =лютий!I33 -> 4.1 | J33: =ROUND(G33*I33,2) -> 266.66 | N33: =ROUND((G33*I33)-K33-L33-M33,2) -> 266.66 | P33: =IF(D33=0,IF((N33-E33-O33)>0,(N33-E33-O33),0),IF((D33+N33-O33)>0,(D33+N33-O33),0)) -> 3587.46 | Q33: =IF(E33=0,IF((D33+N33-O33)<0,ABS(D33+N33-O33),0),IF((N33-E33-O33)<0,ABS(N33-E33-O33),0)) -> 0
A34: 26 | B34: =лютий!B34 -> Замуховська Я.С | C34: =лютий!C34 -> 1026 | D34: =лютий!P34 -> 1445.33 | E34: =лютий!Q34 -> 0 | F34: =лютий!F34 -> 0 | G34: =лютий!G34 -> 49.8 | H34: =лютий!H34 -> 0 | I34: =лютий!I34 -> 4.1 | J34: =ROUND(G34*I34,2) -> 204.18 | N34: =ROUND((G34*I34)-K34-L34-M34,2) -> 204.18 | P34: =IF(D34=0,IF((N34-E34-O34)>0,(N34-E34-O34),0),IF((D34+N34-O34)>0,(D34+N34-O34),0)) -> 1649.51 | Q34: =IF(E34=0,IF((D34+N34-O34)<0,ABS(D34+N34-O34),0),IF((N34-E34-O34)<0,ABS(N34-E34-O34),0)) -> 0
A35: 27 | B35: =лютий!B35 -> Мержиєвська Г.К | C35: =лютий!C35 -> 1027 | D35: =лютий!P35 -> 707.3 | E35: =лютий!Q35 -> 0 | F35: =лютий!F35 -> 0 | G35: =лютий!G35 -> 35.17 | H35: =лютий!H35 -> 0 | I35: =лютий!I35 -> 4.1 | J35: =ROUND(G35*I35,2) -> 144.2 | N35: =ROUND((G35*I35)-K35-L35-M35,2) -> 144.2 | O35: 300 | P35: =IF(D35=0,IF((N35-E35-O35)>0,(N35-E35-O35),0),IF((D35+N35-O35)>0,(D35+N35-O35),0)) -> 551.5 | Q35: =IF(E35=0,IF((D35+N35-O35)<0,ABS(D35+N35-O35),0),IF((N35-E35-O35)<0,ABS(N35-E35-O35),0)) -> 0
A36: 28 | B36: =лютий!B36 -> Кулакова Л.В. | C36: =лютий!C36 -> 1028 | D36: =лютий!P36 -> 485.57 | E36: =лютий!Q36 -> 0 | F36: =лютий!F36 -> 0 | G36: =лютий!G36 -> 62.47 | H36: =лютий!H36 -> 0 | I36: =лютий!I36 -> 4.1 | J36: =ROUND(G36*I36,2) -> 256.13 | N36: =ROUND((G36*I36)-K36-L36-M36,2) -> 256.13 | P36: =IF(D36=0,IF((N36-E36-O36)>0,(N36-E36-O36),0),IF((D36+N36-O36)>0,(D36+N36-O36),0)) -> 741.7 | Q36: =IF(E36=0,IF((D36+N36-O36)<0,ABS(D36+N36-O36),0),IF((N36-E36-O36)<0,ABS(N36-E36-O36),0)) -> 0
A37: 29 | B37: =лютий!B37 -> Бочаров В.Л. | C37: =лютий!C37 -> 1029 | D37: =лютий!P37 -> 2017.8 | E37: =лютий!Q37 -> 0 | F37: =лютий!F37 -> 0 | G37: =лютий!G37 -> 65.75 | H37: =лютий!H37 -> 0 | I37: =лютий!I37 -> 4.1 | J37: =ROUND(G37*I37,2) -> 269.58 | N37: =ROUND((G37*I37)-K37-L37-M37,2) -> 269.58 | P37: =IF(D37=0,IF((N37-E37-O37)>0,(N37-E37-O37),0),IF((D37+N37-O37)>0,(D37+N37-O37),0)) -> 2287.38 | Q37: =IF(E37=0,IF((D37+N37-O37)<0,ABS(D37+N37-O37),0),IF((N37-E37-O37)<0,ABS(N37-E37-O37),0)) -> 0
A38: 30 | B38: =лютий!B38 -> Лучков В.Л. | C38: =лютий!C38 -> 1030 | D38: =лютий!P38 -> 2640.37 | E38: =лютий!Q38 -> 0 | F38: =лютий!F38 -> 0 | G38: =лютий!G38 -> 49.7 | H38: =лютий!H38 -> 0 | I38: =лютий!I38 -> 4.1 | J38: =ROUND(G38*I38,2) -> 203.77 | N38: =ROUND((G38*I38)-K38-L38-M38,2) -> 203.77 | P38: =IF(D38=0,IF((N38-E38-O38)>0,(N38-E38-O38),0),IF((D38+N38-O38)>0,(D38+N38-O38),0)) -> 2844.14 | Q38: =IF(E38=0,IF((D38+N38-O38)<0,ABS(D38+N38-O38),0),IF((N38-E38-O38)<0,ABS(N38-E38-O38),0)) -> 0
A39: 31 | B39: =лютий!B39 -> Кашкар Т.М. | C39: =лютий!C39 -> 1031 | D39: =лютий!P39 -> 0 | E39: =лютий!Q39 -> 5.6843419e-14 | F39: =лютий!F39 -> 0 | G39: =лютий!G39 -> 35.1 | H39: =лютий!H39 -> 0 | I39: =лютий!I39 -> 4.1 | J39: =ROUND(G39*I39,2) -> 143.91 | N39: =ROUND((G39*I39)-K39-L39-M39,2) -> 143.91 | O39: 143.91 | P39: =IF(D39=0,IF((N39-E39-O39)>0,(N39-E39-O39),0),IF((D39+N39-O39)>0,(D39+N39-O39),0)) -> 0 | Q39: =IF(E39=0,IF((D39+N39-O39)<0,ABS(D39+N39-O39),0),IF((N39-E39-O39)<0,ABS(N39-E39-O39),0)) -> 0
A40: 32 | B40: =лютий!B40 -> Стецюк Н.П. | C40: =лютий!C40 -> 1032 | D40: =лютий!P40 -> 2267.25 | E40: =лютий!Q40 -> 0 | F40: =лютий!F40 -> 0 | G40: =лютий!G40 -> 61.9 | H40: =лютий!H40 -> 0 | I40: =лютий!I40 -> 4.1 | J40: =ROUND(G40*I40,2) -> 253.79 | N40: =ROUND((G40*I40)-K40-L40-M40,2) -> 253.79 | P40: =IF(D40=0,IF((N40-E40-O40)>0,(N40-E40-O40),0),IF((D40+N40-O40)>0,(D40+N40-O40),0)) -> 2521.04 | Q40: =IF(E40=0,IF((D40+N40-O40)<0,ABS(D40+N40-O40),0),IF((N40-E40-O40)<0,ABS(N40-E40-O40),0)) -> 0
A41: 33 | B41: =лютий!B41 -> Маханько В.О. | C41: =лютий!C41 -> 1033 | D41: =лютий!P41 -> 1232.64 | E41: =лютий!Q41 -> 0 | F41: =лютий!F41 -> 0 | G41: =лютий!G41 -> 65.53 | H41: =лютий!H41 -> 0 | I41: =лютий!I41 -> 4.1 | J41: =ROUND(G41*I41,2) -> 268.67 | L41: 268.67 | N41: =ROUND((G41*I41)-K41-L41-M41,2) -> 0 | P41: =IF(D41=0,IF((N41-E41-O41)>0,(N41-E41-O41),0),IF((D41+N41-O41)>0,(D41+N41-O41),0)) -> 1232.64 | Q41: =IF(E41=0,IF((D41+N41-O41)<0,ABS(D41+N41-O41),0),IF((N41-E41-O41)<0,ABS(N41-E41-O41),0)) -> 0
A42: 34 | B42: =лютий!B42 -> Реуцька Р.С. | C42: =лютий!C42 -> 1034 | D42: =лютий!P42 -> 1333.28 | E42: =лютий!Q42 -> 0 | F42: =лютий!F42 -> 0 | G42: =лютий!G42 -> 49.7 | H42: =лютий!H42 -> 0 | I42: =лютий!I42 -> 4.1 | J42: =ROUND(G42*I42,2) -> 203.77 | N42: =ROUND((G42*I42)-K42-L42-M42,2) -> 203.77 | P42: =IF(D42=0,IF((N42-E42-O42)>0,(N42-E42-O42),0),IF((D42+N42-O42)>0,(D42+N42-O42),0)) -> 1537.05 | Q42: =IF(E42=0,IF((D42+N42-O42)<0,ABS(D42+N42-O42),0),IF((N42-E42-O42)<0,ABS(N42-E42-O42),0)) -> 0
...

Sheet квітень
A1: ОСББ "Карбишева - 22" | N1: 37465042
B2: Відомість нарахувань та оплати мешканців за утримання будинку
B3: у квітні 2023 року
A6: № кв. | B6: ПІБ | C6: Особ. рах. | D6: Д-Т | E6: К-Т | F6: Пільга % | G6: Заг.площа | H6: Пільг. Площа | I6: Внески | J6: 100% нарах. | K6: Пільгова сума | L6: сплачені суми пільг за реєстрами | M6: Коригування | N6: До сплати | O6: Сплачено | P6: Д-Т | Q6: К-Т
A7: 1 | B7: =березень!B7 -> Бережний В.М. | C7: =березень!C7 -> 1001 | D7: =березень!P7 -> 1841.64 | E7: =березень!Q7 -> 0 | F7: =березень!F7 -> 0 | G7: =березень!G7 -> 64.26 | H7: =березень!H7 -> 0 | I7: =березень!I7 -> 4.1 | J7: =ROUND(G7*I7,2) -> 263.47 | N7: =ROUND((G7*I7)-K7-L7-M7,2) -> 263.47 | O7: 2000 | P7: =IF(D7=0,IF((N7-E7-O7)>0,(N7-E7-O7),0),IF((D7+N7-O7)>0,(D7+N7-O7),0)) -> 105.11 | Q7: =IF(E7=0,IF((D7+N7-O7)<0,ABS(D7+N7-O7),0),IF((N7-E7-O7)<0,ABS(N7-E7-O7),0)) -> 0
A8: 2 | B8: =березень!B8 -> Старикова Т.О. | C8: =березень!C8 -> 1002 | D8: =березень!P8 -> 2923.19 | E8: =березень!Q8 -> 0 | F8: =березень!F8 -> 0 | G8: =березень!G8 -> 48.71 | H8: =березень!H8 -> 0 | I8: =березень!I8 -> 4.1 | J8: =ROUND(G8*I8,2) -> 199.71 | N8: =ROUND((G8*I8)-K8-L8-M8,2) -> 199.71 | P8: =IF(D8=0,IF((N8-E8-O8)>0,(N8-E8-O8),0),IF((D8+N8-O8)>0,(D8+N8-O8),0)) -> 3122.9 | Q8: =IF(E8=0,IF((D8+N8-O8)<0,ABS(D8+N8-O8),0),IF((N8-E8-O8)<0,ABS(N8-E8-O8),0)) -> 0
A9: 3 | B9: =березень!B9 -> Мазур Т.В. | C9: =березень!C9 -> 1003 | D9: =березень!P9 -> 168 | E9: =березень!Q9 -> 0 | F9: =березень!F9 -> 0 | G9: =березень!G9 -> 35 | H9: =березень!H9 -> 0 | I9: =березень!I9 -> 4.1 | J9: =ROUND(G9*I9,2) -> 143.5 | N9: =ROUND((G9*I9)-K9-L9-M9,2) -> 143.5 | O9: 300 | P9: =IF(D9=0,IF((N9-E9-O9)>0,(N9-E9-O9),0),IF((D9+N9-O9)>0,(D9+N9-O9),0)) -> 11.5 | Q9: =IF(E9=0,IF((D9+N9-O9)<0,ABS(D9+N9-O9),0),IF((N9-E9-O9)<0,ABS(N9-E9-O9),0)) -> 0
A10: 4 | B10: =березень!B10 -> Сокол О.В. | C10: =березень!C10 -> 1004 | D10: =березень!P10 -> 0 | E10: =березень!Q10 -> 0.03 | F10: =березень!F10 -> 0 | G10: =березень!G10 -> 61.6 | H10: =березень!H10 -> 0 | I10: =березень!I10 -> 4.1 | J10: =ROUND(G10*I10,2) -> 252.56 | N10: =ROUND((G10*I10)-K10-L10-M10,2) -> 252.56 | O10: =252.56+252.56 -> 505.12 | P10: =IF(D10=0,IF((N10-E10-O10)>0,(N10-E10-O10),0),IF((D10+N10-O10)>0,(D10+N10-O10),0)) -> 0 | Q10: =IF(E10=0,IF((D10+N10-O10)<0,ABS(D10+N10-O10),0),IF((N10-E10-O10)<0,ABS(N10-E10-O10),0)) -> 252.59
A11: 5 | B11: =березень!B11 -> Семко Л.І. | C11: =березень!C11 -> 1005 | D11: =березень!P11 -> 0 | E11: =березень!Q11 -> 490.4 | F11: =березень!F11 -> 0 | G11: =березень!G11 -> 28.34 | H11: =березень!H11 -> 0 | I11: =березень!I11 -> 4.1 | J11: =ROUND(G11*I11,2) -> 116.19 | N11: =ROUND((G11*I11)-K11-L11-M11,2) -> 116.19 | P11: =IF(D11=0,IF((N11-E11-O11)>0,(N11-E11-O11),0),IF((D11+N11-O11)>0,(D11+N11-O11),0)) -> 0 | Q11: =IF(E11=0,IF((D11+N11-O11)<0,ABS(D11+N11-O11),0),IF((N11-E11-O11)<0,ABS(N11-E11-O11),0)) -> 374.21
A12: 5 | B12: =березень!B12 -> Гаркуша Н.І. | C12: =березень!C12 -> 1005-а | D12: =березень!P12 -> 0 | E12: =березень!Q12 -> 250.97 | F12: =березень!F12 -> 0 | G12: =березень!G12 -> 36.66 | H12: =березень!H12 -> 0 | I12: =березень!I12 -> 4.1 | J12: =ROUND(G12*I12,2) -> 150.31 | N12: =ROUND((G12*I12)-K12-L12-M12,2) -> 150.31 | P12: =IF(D12=0,IF((N12-E12-O12)>0,(N12-E12-O12),0),IF((D12+N12-O12)>0,(D12+N12-O12),0)) -> 0 | Q12: =IF(E12=0,IF((D12+N12-O12)<0,ABS(D12+N12-O12),0),IF((N12-E12-O12)<0,ABS(N12-E12-O12),0)) -> 100.66
A13: 6 | B13: =березень!B13 -> Андріяшев В.М | C13: =березень!C13 -> 1006 | D13: =березень!P13 -> 0 | E13: =березень!Q13 -> 173.38 | F13: =березень!F13 -> 0 | G13: =березень!G13 -> 49.8 | H13: =березень!H13 -> 0 | I13: =березень!I13 -> 4.1 | J13: =ROUND(G13*I13,2) -> 204.18 | N13: =ROUND((G13*I13)-K13-L13-M13,2) -> 204.18 | P13: =IF(D13=0,IF((N13-E13-O13)>0,(N13-E13-O13),0),IF((D13+N13-O13)>0,(D13+N13-O13),0)) -> 30.8 | Q13: =IF(E13=0,IF((D13+N13-O13)<0,ABS(D13+N13-O13),0),IF((N13-E13-O13)<0,ABS(N13-E13-O13),0)) -> 0
A14: 7 | B14: =березень!B14 -> Старчикова О.М. | C14: =березень!C14 -> 1007 | D14: =березень!P14 -> 140.05 | E14: =березень!Q14 -> 0 | F14: =березень!F14 -> 0 | G14: =березень!G14 -> 34.65 | H14: =березень!H14 -> 0 | I14: =березень!I14 -> 4.1 | J14: =ROUND(G14*I14,2) -> 142.07 | N14: =ROUND((G14*I14)-K14-L14-M14,2) -> 142.07 | O14: 141 | P14: =IF(D14=0,IF((N14-E14-O14)>0,(N14-E14-O14),0),IF((D14+N14-O14)>0,(D14+N14-O14),0)) -> 141.12 | Q14: =IF(E14=0,IF((D14+N14-O14)<0,ABS(D14+N14-O14),0),IF((N14-E14-O14)<0,ABS(N14-E14-O14),0)) -> 0
A15: 8 | B15: =березень!B15 -> Безер Т.М | C15: =березень!C15 -> 1008 | D15: =березень!P15 -> 735.56 | E15: =березень!Q15 -> 0 | F15: =березень!F15 -> 0 | G15: =березень!G15 -> 62.14 | H15: =березень!H15 -> 0 | I15: =березень!I15 -> 4.1 | J15: =ROUND(G15*I15,2) -> 254.77 | N15: =ROUND((G15*I15)-K15-L15-M15,2) -> 254.77 | O15: 765 | P15: =IF(D15=0,IF((N15-E15-O15)>0,(N15-E15-O15),0),IF((D15+N15-O15)>0,(D15+N15-O15),0)) -> 225.33 | Q15: =IF(E15=0,IF((D15+N15-O15)<0,ABS(D15+N15-O15),0),IF((N15-E15-O15)<0,ABS(N15-E15-O15),0)) -> 0
A16: 9 | B16: =березень!B16 -> Решетило М.М | C16: =березень!C16 -> 1009 | D16: =березень!P16 -> 3707.44 | E16: =березень!Q16 -> 0 | F16: =березень!F16 -> 0 | G16: =березень!G16 -> 65.16 | H16: =березень!H16 -> 0 | I16: =березень!I16 -> 4.1 | J16: =ROUND(G16*I16,2) -> 267.16 | N16: =ROUND((G16*I16)-K16-L16-M16,2) -> 267.16 | O16: 2000 | P16: =IF(D16=0,IF((N16-E16-O16)>0,(N16-E16-O16),0),IF((D16+N16-O16)>0,(D16+N16-O16),0)) -> 1974.6 | Q16: =IF(E16=0,IF((D16+N16-O16)<0,ABS(D16+N16-O16),0),IF((N16-E16-O16)<0,ABS(N16-E16-O16),0)) -> 0
A17: 10 | B17: =березень!B17 -> Фесенко О.В. | C17: =березень!C17 -> 1010 | D17: =березень!P17 -> 2198.16 | E17: =березень!Q17 -> 0 | F17: =березень!F17 -> 0 | G17: =березень!G17 -> 50.1 | H17: =березень!H17 -> 0 | I17: =березень!I17 -> 4.1 | J17: =ROUND(G17*I17,2) -> 205.41 | N17: =ROUND((G17*I17)-K17-L17-M17,2) -> 205.41 | P17: =IF(D17=0,IF((N17-E17-O17)>0,(N17-E17-O17),0),IF((D17+N17-O17)>0,(D17+N17-O17),0)) -> 2403.57 | Q17: =IF(E17=0,IF((D17+N17-O17)<0,ABS(D17+N17-O17),0),IF((N17-E17-O17)<0,ABS(N17-E17-O17),0)) -> 0
A18: 11 | B18: =березень!B18 -> Петренко О.М. | C18: =березень!C18 -> 1011 | D18: =березень!P18 -> 1785.64 | E18: =березень!Q18 -> 0 | F18: =березень!F18 -> 0 | G18: =березень!G18 -> 35.2 | H18: =березень!H18 -> 0 | I18: =березень!I18 -> 4.1 | J18: =ROUND(G18*I18,2) -> 144.32 | N18: =ROUND((G18*I18)-K18-L18-M18,2) -> 144.32 | P18: =IF(D18=0,IF((N18-E18-O18)>0,(N18-E18-O18),0),IF((D18+N18-O18)>0,(D18+N18-O18),0)) -> 1929.96 | Q18: =IF(E18=0,IF((D18+N18-O18)<0,ABS(D18+N18-O18),0),IF((N18-E18-O18)<0,ABS(N18-E18-O18),0)) -> 0
A19: 12 | B19: =березень!B19 -> Зеленюк А.Д | C19: =березень!C19 -> 1012 | D19: =березень!P19 -> 3685.41 | E19: =березень!Q19 -> 0 | F19: =березень!F19 -> 0 | G19: =березень!G19 -> 62.78 | H19: =березень!H19 -> 0 | I19: =березень!I19 -> 4.1 | J19: =ROUND(G19*I19,2) -> 257.4 | N19: =ROUND((G19*I19)-K19-L19-M19,2) -> 257.4 | P19: =IF(D19=0,IF((N19-E19-O19)>0,(N19-E19-O19),0),IF((D19+N19-O19)>0,(D19+N19-O19),0)) -> 3942.81 | Q19: =IF(E19=0,IF((D19+N19-O19)<0,ABS(D19+N19-O19),0),IF((N19-E19-O19)<0,ABS(N19-E19-O19),0)) -> 0
A20: 13 | B20: =березень!B20 -> Вовк І.В | C20: =березень!C20 -> 1013 | D20: =березень!P20 -> 2484.09 | E20: =березень!Q20 -> 0 | F20: =березень!F20 -> 0 | G20: =березень!G20 -> 28.23 | H20: =березень!H20 -> 0 | I20: =березень!I20 -> 4.1 | J20: =ROUND(G20*I20,2) -> 115.74 | N20: =ROUND((G20*I20)-K20-L20-M20,2) -> 115.74 | P20: =IF(D20=0,IF((N20-E20-O20)>0,(N20-E20-O20),0),IF((D20+N20-O20)>0,(D20+N20-O20),0)) -> 2599.83 | Q20: =IF(E20=0,IF((D20+N20-O20)<0,ABS(D20+N20-O20),0),IF((N20-E20-O20)<0,ABS(N20-E20-O20),0)) -> 0
